INFO:root:{
    "2022-07-11 15:11:48": {
        "pnl": 0.0,
        "price": 12927.2,
        "symbol": "DE40"
    },
    "2022-07-11 16:45:28": {
        "pnl": 457.5,
        "price": 12896.7,
        "symbol": "DE40"
    },
    "PYTHON_message_reception_timestamp": "2022-07-11 14:08:21 .356148MS",
    "total_pnl": 457.5
}
DEBUG:telethon.extensions.messagepacker:Assigned msg_id = 7119085680993105076 to SendMessageRequest (23313854490)
DEBUG:telethon.network.mtprotosender:Encrypting 1 message(s) in 384 bytes for sending
DEBUG:telethon.network.mtprotosender:Encrypted messages put in a queue to be sent
DEBUG:telethon.network.mtprotosender:Waiting for messages to send...
DEBUG:telethon.extensions.messagepacker:Assigned msg_id = 7119085681001147412 to MsgsAck (2331383e580)
DEBUG:telethon.network.mtprotosender:Encrypting 1 message(s) in 68 bytes for sending
DEBUG:telethon.network.mtprotosender:Encrypted messages put in a queue to be sent
DEBUG:telethon.network.mtprotosender:Waiting for messages to send...
DEBUG:telethon.network.mtprotosender:Handling RPC result for message 7119085680993105076
DEBUG:telethon.network.mtprotosender:Receiving items from the network...
DEBUG:telethon.network.mtprotosender:Handling update UpdateShort
DEBUG:telethon.network.mtprotosender:Receiving items from the network...
DEBUG:telethon.extensions.messagepacker:Assigned msg_id = 7119377004503407536 to PingRequest (233138119d0)
DEBUG:telethon.extensions.messagepacker:Assigned msg_id = 7119377004503407540 to GetStateRequest (23313811df0)
DEBUG:telethon.network.mtprotosender:Encrypting 2 message(s) in 72 bytes for sending
DEBUG:telethon.network.mtprotosender:Encrypted messages put in a queue to be sent
DEBUG:telethon.network.mtprotosender:Waiting for messages to send...
DEBUG:telethon.extensions.messagepacker:Assigned msg_id = 7119377004515406664 to MsgsAck (2331383ed30)
DEBUG:telethon.network.mtprotosender:Encrypting 1 message(s) in 44 bytes for sending
DEBUG:telethon.network.mtprotosender:Encrypted messages put in a queue to be sent
DEBUG:telethon.network.mtprotosender:Waiting for messages to send...
INFO:telethon.network.connection.connection:The server closed the connection
INFO:telethon.network.connection.connection:<class 'ConnectionResetError'> during disconnect: [WinError 64] The specified network name is no longer available
INFO:telethon.network.mtprotosender:Connection closed while receiving data
INFO:telethon.network.mtprotosender:Closing current connection to begin reconnect...
INFO:telethon.network.connection.connection:<class 'ConnectionResetError'> during disconnect: [WinError 64] The specified network name is no longer available
INFO:telethon.network.mtprotosender:Connecting to 149.154.167.92:443/TcpFull...
DEBUG:telethon.network.mtprotosender:Connection attempt 1...
DEBUG:telethon.network.mtprotosender:Connection success!
DEBUG:telethon.network.mtprotosender:Starting send loop
DEBUG:telethon.network.mtprotosender:Starting receive loop
INFO:telethon.network.mtprotosender:Connection to 149.154.167.92:443/TcpFull complete!
DEBUG:telethon.network.mtprotosender:Waiting for messages to send...
DEBUG:telethon.extensions.messagepacker:Assigned msg_id = 7119377021342838832 to PingRequest (233138119d0)
DEBUG:telethon.extensions.messagepacker:Assigned msg_id = 7119377021342838836 to GetStateRequest (23313811df0)
DEBUG:telethon.network.mtprotosender:Encrypting 2 message(s) in 72 bytes for sending
DEBUG:telethon.network.mtprotosender:Encrypted messages put in a queue to be sent
DEBUG:telethon.network.mtprotosender:Waiting for messages to send...
DEBUG:telethon.network.mtprotosender:Receiving items from the network...
DEBUG:telethon.extensions.messagepacker:Assigned msg_id = 7119377021354808396 to GetUsersRequest (2331383e4c0)
DEBUG:telethon.network.mtprotosender:Encrypting 1 message(s) in 32 bytes for sending
DEBUG:telethon.network.mtprotosender:Encrypted messages put in a queue to be sent
DEBUG:telethon.network.mtprotosender:Waiting for messages to send...
DEBUG:telethon.network.mtprotosender:Handling bad salt for message 7119377021342838840
DEBUG:telethon.network.mtprotosender:2 message(s) will be resent
DEBUG:telethon.network.mtprotosender:Receiving items from the network...
DEBUG:telethon.extensions.messagepacker:Assigned msg_id = 7119377026591067504 to PingRequest (233138119d0)
DEBUG:telethon.extensions.messagepacker:Assigned msg_id = 7119377026591067508 to GetStateRequest (23313811df0)
DEBUG:telethon.network.mtprotosender:Encrypting 2 message(s) in 72 bytes for sending
DEBUG:telethon.network.mtprotosender:Encrypted messages put in a queue to be sent
DEBUG:telethon.network.mtprotosender:Waiting for messages to send...
DEBUG:telethon.extensions.messagepacker:Assigned msg_id = 7119377026599065968 to MsgsAck (23313811970)
DEBUG:telethon.network.mtprotosender:Encrypting 1 message(s) in 36 bytes for sending
DEBUG:telethon.network.mtprotosender:Handling bad salt for message 7119377021354808396
DEBUG:telethon.network.mtprotosender:1 message(s) will be resent
DEBUG:telethon.network.mtprotosender:Receiving items from the network...
DEBUG:telethon.network.mtprotosender:Encrypted messages put in a queue to be sent
DEBUG:telethon.network.mtprotosender:Waiting for messages to send...
DEBUG:telethon.extensions.messagepacker:Assigned msg_id = 7119377026615043828 to GetUsersRequest (2331383e4c0)
DEBUG:telethon.extensions.messagepacker:Assigned msg_id = 7119377026615043832 to MsgsAck (2331383eac0)
DEBUG:telethon.network.mtprotosender:Encrypting 2 message(s) in 92 bytes for sending
DEBUG:telethon.network.mtprotosender:Encrypted messages put in a queue to be sent
DEBUG:telethon.network.mtprotosender:Waiting for messages to send...
DEBUG:telethon.network.mtprotosender:Handling container
DEBUG:telethon.network.mtprotosender:Handling new session created
DEBUG:telethon.network.mtprotosender:Handling pong for message 7119377026591067504
DEBUG:telethon.network.mtprotosender:Handling acknowledge for [7119377026591067508]
DEBUG:telethon.network.mtprotosender:Receiving items from the network...
DEBUG:telethon.network.mtprotosender:Handling RPC result for message 7119377026615043828
DEBUG:telethon.network.mtprotosender:Receiving items from the network...
DEBUG:telethon.network.mtprotosender:Handling RPC result for message 7119377026591067508
DEBUG:telethon.network.mtprotosender:Receiving items from the network...
DEBUG:telethon.extensions.messagepacker:Assigned msg_id = 7119377035504493192 to GetStateRequest (23313811df0)
DEBUG:telethon.network.mtprotosender:Encrypting 1 message(s) in 20 bytes for sending
DEBUG:telethon.network.mtprotosender:Encrypted messages put in a queue to be sent
DEBUG:telethon.network.mtprotosender:Waiting for messages to send...
DEBUG:telethon.extensions.messagepacker:Assigned msg_id = 7119377035508494808 to MsgsAck (23313854b80)
DEBUG:telethon.network.mtprotosender:Encrypting 1 message(s) in 76 bytes for sending
DEBUG:telethon.network.mtprotosender:Encrypted messages put in a queue to be sent
DEBUG:telethon.network.mtprotosender:Waiting for messages to send...
DEBUG:telethon.network.mtprotosender:Handling RPC result for message 7119377035504493192
DEBUG:telethon.network.mtprotosender:Receiving items from the network...
DEBUG:telethon.network.mtprotosender:Handling update UpdateShort
DEBUG:telethon.network.mtprotosender:Receiving items from the network...
DEBUG:telethon.extensions.messagepacker:Assigned msg_id = 7119377299924177504 to PingRequest (23313811df0)
DEBUG:telethon.network.mtprotosender:Encrypting 1 message(s) in 28 bytes for sending
DEBUG:telethon.network.mtprotosender:Encrypted messages put in a queue to be sent
DEBUG:telethon.network.mtprotosender:Waiting for messages to send...
DEBUG:telethon.extensions.messagepacker:Assigned msg_id = 7119377299928168628 to MsgsAck (23313811f10)
DEBUG:telethon.network.mtprotosender:Encrypting 1 message(s) in 44 bytes for sending
DEBUG:telethon.network.mtprotosender:Encrypted messages put in a queue to be sent
DEBUG:telethon.network.mtprotosender:Waiting for messages to send...
DEBUG:telethon.network.mtprotosender:Handling pong for message 7119377299924177504
DEBUG:telethon.network.mtprotosender:Receiving items from the network...
INFO:telethon.network.mtprotosender:Disconnecting from 149.154.167.92:443/TcpFull...
DEBUG:telethon.network.mtprotosender:Closing current connection...
DEBUG:telethon.network.mtprotosender:Cancelling 0 pending message(s)...
INFO:telethon.network.mtprotosender:Disconnection from 149.154.167.92:443/TcpFull complete!
INFO:telethon.network.mtprotosender:Not disconnecting (already have no connection)
ERROR:asyncio:Task exception was never retrieved
future: <Task finished name='Task-62' coro=<UpdateMethods._dispatch_update() done, defined at C:\Users\caleb\OneDrive\Desktop\Dev Projects\Python Projects\trade_bot - Copy\venv\lib\site-packages\telethon\client\updates.py:399> exception=KeyboardInterrupt()>
Traceback (most recent call last):
  File "C:\Users\caleb\OneDrive\Desktop\Dev Projects\Python Projects\trade_bot - Copy\venv\lib\site-packages\telethon\client\updates.py", line 84, in run_until_disconnected
    return self.loop.run_until_complete(self._run_until_disconnected())
  File "C:\Users\caleb\AppData\Local\Programs\Python\Python39\lib\asyncio\base_events.py", line 629, in run_until_complete
    self.run_forever()
  File "C:\Users\caleb\AppData\Local\Programs\Python\Python39\lib\asyncio\windows_events.py", line 316, in run_forever
    super().run_forever()
  File "C:\Users\caleb\AppData\Local\Programs\Python\Python39\lib\asyncio\base_events.py", line 596, in run_forever
    self._run_once()
  File "C:\Users\caleb\AppData\Local\Programs\Python\Python39\lib\asyncio\base_events.py", line 1890, in _run_once
    handle._run()
  File "C:\Users\caleb\AppData\Local\Programs\Python\Python39\lib\asyncio\events.py", line 80, in _run
    self._context.run(self._callback, *self._args)
  File "C:\Users\caleb\OneDrive\Desktop\Dev Projects\Python Projects\trade_bot - Copy\venv\lib\site-packages\telethon\client\updates.py", line 467, in _dispatch_update
    await callback(event)
  File "C:\Users\caleb\OneDrive\Desktop\Dev Projects\Python Projects\trade_bot - Copy\main.py", line 35, in handler
    blotter_message_json = blotter.trade_position(message_json)
  File "C:\Users\caleb\OneDrive\Desktop\Dev Projects\Python Projects\trade_bot - Copy\blotter\daily_blotter.py", line 65, in trade_position
    self.modify_stop_loss()
  File "C:\Users\caleb\OneDrive\Desktop\Dev Projects\Python Projects\trade_bot - Copy\blotter\daily_blotter.py", line 148, in modify_stop_loss
    confirmation_message = self.connector.modify_stop_loss_for_symbol(symbol = symbol,new_stop_level= self.message_json["stop_loss_level"])
  File "C:\Users\caleb\OneDrive\Desktop\Dev Projects\Python Projects\trade_bot - Copy\connectors\meta_trader_5.py", line 275, in modify_stop_loss_for_symbol
    results[str(position['ticket'])] = self.modify_stop_loss_for_ticket(ticket = position['ticket'], new_stop_level = new_stop_level)
  File "C:\Users\caleb\OneDrive\Desktop\Dev Projects\Python Projects\trade_bot - Copy\connectors\meta_trader_5.py", line 254, in modify_stop_loss_for_ticket
    result = mt5.order_send(request)
KeyboardInterrupt
ERROR:telethon.client.updates:Unhandled exception on handler
Traceback (most recent call last):
  File "C:\Users\caleb\OneDrive\Desktop\Dev Projects\Python Projects\trade_bot - Copy\venv\lib\site-packages\telethon\client\updates.py", line 467, in _dispatch_update
    await callback(event)
  File "C:\Users\caleb\OneDrive\Desktop\Dev Projects\Python Projects\trade_bot - Copy\main.py", line 35, in handler
    blotter_message_json = blotter.trade_position(message_json)
  File "C:\Users\caleb\OneDrive\Desktop\Dev Projects\Python Projects\trade_bot - Copy\blotter\daily_blotter.py", line 62, in trade_position
    self.close_n_previous_trades()
  File "C:\Users\caleb\OneDrive\Desktop\Dev Projects\Python Projects\trade_bot - Copy\blotter\daily_blotter.py", line 118, in close_n_previous_trades
    confirmation = self.connector.close_market_order_by_order_of_open(symbol = symbol, order = i)
  File "C:\Users\caleb\OneDrive\Desktop\Dev Projects\Python Projects\trade_bot - Copy\connectors\meta_trader_5.py", line 207, in close_market_order_by_order_of_open
    pertinent_date = dates[order]
IndexError: list index out of range
WARNING:telethon.network.mtprotosender:Attempt 1 at connecting failed: TimeoutError: 
WARNING:telethon.network.mtprotosender:Attempt 1 at connecting failed: TimeoutError: 
WARNING:telethon.network.mtprotosender:Attempt 1 at connecting failed: TimeoutError: 
WARNING:telethon.network.mtprotosender:Attempt 2 at connecting failed: TimeoutError: 
WARNING:telethon.network.mtprotosender:Attempt 3 at connecting failed: TimeoutError: 
WARNING:telethon.network.mtprotosender:Attempt 4 at connecting failed: TimeoutError: 
WARNING:telethon.network.mtprotosender:Attempt 5 at connecting failed: TimeoutError: 
WARNING:telethon.network.mtprotosender:Attempt 1 at connecting failed: TimeoutError: 
WARNING:telethon.network.mtprotosender:Security error while unpacking a received message: Server replied with a wrong session ID
WARNING:telethon.network.mtprotosender:Security error while unpacking a received message: Server replied with a wrong session ID
WARNING:telethon.network.mtprotosender:Security error while unpacking a received message: Server replied with a wrong session ID
WARNING:telethon.network.mtprotosender:Attempt 1 at connecting failed: TimeoutError: 
WARNING:telethon.network.mtprotosender:Attempt 2 at connecting failed: TimeoutError: 
WARNING:telethon.network.mtprotosender:Attempt 1 at connecting failed: TimeoutError: 
WARNING:telethon.network.mtprotosender:Attempt 2 at connecting failed: TimeoutError: 
WARNING:telethon.network.mtprotosender:Attempt 1 at connecting failed: TimeoutError: 
WARNING:telethon.network.mtprotosender:Attempt 1 at connecting failed: TimeoutError: 
WARNING:telethon.network.mtprotosender:Attempt 2 at connecting failed: TimeoutError: 
WARNING:telethon.network.mtprotosender:Attempt 1 at connecting failed: TimeoutError: 
WARNING:telethon.network.mtprotosender:Attempt 1 at connecting failed: TimeoutError: 
WARNING:telethon.network.mtprotosender:Attempt 2 at connecting failed: TimeoutError: 
WARNING:telethon.network.mtprotosender:Attempt 3 at connecting failed: TimeoutError: 
WARNING:telethon.network.mtprotosender:Attempt 1 at connecting failed: TimeoutError: 
WARNING:telethon.network.mtprotosender:Attempt 1 at connecting failed: TimeoutError: 
WARNING:telethon.network.mtprotosender:Attempt 1 at connecting failed: TimeoutError: 
WARNING:telethon.network.mtprotosender:Attempt 2 at connecting failed: TimeoutError: 
WARNING:telethon.network.mtprotosender:Attempt 3 at connecting failed: TimeoutError: 
WARNING:telethon.network.mtprotosender:Attempt 4 at connecting failed: TimeoutError: 
WARNING:telethon.network.mtprotosender:Attempt 1 at connecting failed: TimeoutError: 
WARNING:telethon.network.mtprotosender:Attempt 2 at connecting failed: TimeoutError: 
WARNING:telethon.network.mtprotosender:Attempt 1 at connecting failed: TimeoutError: 
WARNING:telethon.network.mtprotosender:Attempt 2 at connecting failed: TimeoutError: 
WARNING:telethon.network.mtprotosender:Attempt 3 at connecting failed: TimeoutError: 
WARNING:telethon.network.mtprotosender:Attempt 1 at connecting failed: TimeoutError: 
WARNING:telethon.network.mtprotosender:Attempt 2 at connecting failed: TimeoutError: 
WARNING:telethon.network.mtprotosender:Attempt 3 at connecting failed: TimeoutError: 
WARNING:telethon.network.mtprotosender:Attempt 4 at connecting failed: TimeoutError: 
WARNING:telethon.network.mtprotosender:Attempt 5 at connecting failed: TimeoutError: 
WARNING:telethon.network.mtprotosender:Attempt 1 at connecting failed: TimeoutError: 
WARNING:telethon.network.mtprotosender:Attempt 1 at connecting failed: TimeoutError: 
WARNING:telethon.network.mtprotosender:Attempt 2 at connecting failed: TimeoutError: 
WARNING:telethon.network.mtprotosender:Attempt 3 at connecting failed: TimeoutError: 
WARNING:telethon.network.mtprotosender:Attempt 4 at connecting failed: TimeoutError: 
WARNING:telethon.network.mtprotosender:Attempt 1 at connecting failed: TimeoutError: 
WARNING:telethon.network.mtprotosender:Attempt 2 at connecting failed: TimeoutError: 
WARNING:telethon.network.mtprotosender:Attempt 3 at connecting failed: TimeoutError: 
WARNING:telethon.network.mtprotosender:Attempt 1 at connecting failed: TimeoutError: 
WARNING:telethon.network.mtprotosender:Attempt 2 at connecting failed: TimeoutError: 
WARNING:telethon.network.mtprotosender:Attempt 3 at connecting failed: TimeoutError: 
WARNING:telethon.network.mtprotosender:Attempt 4 at connecting failed: TimeoutError: 
WARNING:telethon.network.mtprotosender:Attempt 5 at connecting failed: TimeoutError: 
WARNING:telethon.network.mtprotosender:Attempt 6 at connecting failed: TimeoutError: 
WARNING:telethon.network.mtprotosender:Attempt 1 at connecting failed: TimeoutError: 
WARNING:telethon.network.mtprotosender:Attempt 2 at connecting failed: TimeoutError: 
WARNING:telethon.network.mtprotosender:Attempt 3 at connecting failed: TimeoutError: 
WARNING:telethon.network.mtprotosender:Attempt 4 at connecting failed: TimeoutError: 
WARNING:telethon.network.mtprotosender:Attempt 5 at connecting failed: TimeoutError: 
WARNING:telethon.network.mtprotosender:Attempt 6 at connecting failed: TimeoutError: 
WARNING:telethon.network.mtprotosender:Attempt 1 at connecting failed: TimeoutError: 
WARNING:telethon.network.mtprotosender:Attempt 2 at connecting failed: TimeoutError: 
WARNING:telethon.network.mtprotosender:Attempt 3 at connecting failed: TimeoutError: 
WARNING:telethon.network.mtprotosender:Attempt 4 at connecting failed: TimeoutError: 
WARNING:telethon.network.mtprotosender:Attempt 5 at connecting failed: TimeoutError: 
WARNING:telethon.network.mtprotosender:Attempt 6 at connecting failed: TimeoutError: 
WARNING:telethon.network.mtprotosender:Attempt 1 at connecting failed: TimeoutError: 
WARNING:telethon.network.mtprotosender:Attempt 2 at connecting failed: TimeoutError: 
WARNING:telethon.network.mtprotosender:Attempt 3 at connecting failed: TimeoutError: 
WARNING:telethon.network.mtprotosender:Attempt 4 at connecting failed: TimeoutError: 
WARNING:telethon.network.mtprotosender:Attempt 5 at connecting failed: TimeoutError: 
WARNING:telethon.network.mtprotosender:Attempt 6 at connecting failed: TimeoutError: 
WARNING:telethon.network.mtprotosender:Attempt 1 at connecting failed: TimeoutError: 
WARNING:telethon.network.mtprotosender:Attempt 2 at connecting failed: TimeoutError: 
WARNING:telethon.network.mtprotosender:Attempt 3 at connecting failed: TimeoutError: 
WARNING:telethon.network.mtprotosender:Attempt 4 at connecting failed: TimeoutError: 
WARNING:telethon.network.mtprotosender:Attempt 1 at connecting failed: TimeoutError: 
WARNING:telethon.network.mtprotosender:Attempt 2 at connecting failed: TimeoutError: 
WARNING:telethon.network.mtprotosender:Attempt 3 at connecting failed: TimeoutError: 
WARNING:telethon.network.mtprotosender:Attempt 4 at connecting failed: TimeoutError: 
WARNING:telethon.network.mtprotosender:Attempt 5 at connecting failed: TimeoutError: 
WARNING:telethon.network.mtprotosender:Attempt 6 at connecting failed: TimeoutError: 
WARNING:telethon.network.mtprotosender:Attempt 1 at connecting failed: TimeoutError: 
WARNING:telethon.network.mtprotosender:Attempt 2 at connecting failed: TimeoutError: 
WARNING:telethon.network.mtprotosender:Attempt 3 at connecting failed: TimeoutError: 
WARNING:telethon.network.mtprotosender:Attempt 4 at connecting failed: TimeoutError: 
WARNING:telethon.network.mtprotosender:Attempt 5 at connecting failed: TimeoutError: 
WARNING:telethon.network.mtprotosender:Attempt 6 at connecting failed: TimeoutError: 
WARNING:telethon.network.mtprotosender:Attempt 1 at connecting failed: TimeoutError: 
WARNING:telethon.network.mtprotosender:Attempt 2 at connecting failed: TimeoutError: 
WARNING:telethon.network.mtprotosender:Attempt 3 at connecting failed: TimeoutError: 
WARNING:telethon.network.mtprotosender:Attempt 4 at connecting failed: TimeoutError: 
WARNING:telethon.network.mtprotosender:Attempt 5 at connecting failed: TimeoutError: 
WARNING:telethon.network.mtprotosender:Attempt 6 at connecting failed: TimeoutError: 
WARNING:telethon.network.mtprotosender:Attempt 1 at connecting failed: TimeoutError: 
WARNING:telethon.network.mtprotosender:Attempt 2 at connecting failed: TimeoutError: 
WARNING:telethon.network.mtprotosender:Attempt 3 at connecting failed: TimeoutError: 
WARNING:telethon.network.mtprotosender:Attempt 4 at connecting failed: TimeoutError: 
WARNING:telethon.network.mtprotosender:Attempt 5 at connecting failed: TimeoutError: 
WARNING:telethon.network.mtprotosender:Attempt 6 at connecting failed: TimeoutError: 
WARNING:telethon.network.mtprotosender:Attempt 1 at connecting failed: TimeoutError: 
WARNING:telethon.network.mtprotosender:Attempt 2 at connecting failed: TimeoutError: 
WARNING:telethon.network.mtprotosender:Attempt 3 at connecting failed: TimeoutError: 
WARNING:telethon.network.mtprotosender:Attempt 4 at connecting failed: TimeoutError: 
WARNING:telethon.network.mtprotosender:Attempt 5 at connecting failed: TimeoutError: 
WARNING:telethon.network.mtprotosender:Attempt 6 at connecting failed: TimeoutError: 
ERROR:telethon.network.mtprotosender:Automatic reconnection failed 5 time(s)
ERROR:asyncio:Future exception was never retrieved
future: <Future finished exception=ConnectionError('Connection to Telegram failed 5 time(s)')>
ConnectionError: Connection to Telegram failed 5 time(s)
ERROR:telethon.client.updates:Unhandled exception on handler
Traceback (most recent call last):
  File "C:\Users\caleb\OneDrive\Desktop\Dev Projects\Python Projects\trade_bot - Copy\venv\lib\site-packages\telethon\client\updates.py", line 467, in _dispatch_update
    await callback(event)
  File "C:\Users\caleb\OneDrive\Desktop\Dev Projects\Python Projects\trade_bot - Copy\run_bot.py", line 35, in handler
    blotter_message_json = blotter.trade_position(message_json)
  File "C:\Users\caleb\OneDrive\Desktop\Dev Projects\Python Projects\trade_bot - Copy\blotter\daily_blotter.py", line 56, in trade_position
    self.close_oldest_index_position()
  File "C:\Users\caleb\OneDrive\Desktop\Dev Projects\Python Projects\trade_bot - Copy\blotter\daily_blotter.py", line 139, in close_oldest_index_position
    confirmation = self.connector.close_market_order_by_order_of_open(symbol = symbol, first = True)
  File "C:\Users\caleb\OneDrive\Desktop\Dev Projects\Python Projects\trade_bot - Copy\connectors\meta_trader_5.py", line 207, in close_market_order_by_order_of_open
    pertinent_date = dates[order]
IndexError: list index out of range
ERROR:telethon.client.updates:Unhandled exception on handler
Traceback (most recent call last):
  File "C:\Users\caleb\OneDrive\Desktop\Dev Projects\Python Projects\trade_bot - Copy\venv\lib\site-packages\telethon\client\updates.py", line 467, in _dispatch_update
    await callback(event)
  File "C:\Users\caleb\OneDrive\Desktop\Dev Projects\Python Projects\trade_bot - Copy\run_bot.py", line 35, in handler
    blotter_message_json = blotter.trade_position(message_json)
  File "C:\Users\caleb\OneDrive\Desktop\Dev Projects\Python Projects\trade_bot - Copy\blotter\daily_blotter.py", line 56, in trade_position
    self.close_oldest_index_position()
  File "C:\Users\caleb\OneDrive\Desktop\Dev Projects\Python Projects\trade_bot - Copy\blotter\daily_blotter.py", line 139, in close_oldest_index_position
    confirmation = self.connector.close_market_order_by_order_of_open(symbol = symbol, first = True)
  File "C:\Users\caleb\OneDrive\Desktop\Dev Projects\Python Projects\trade_bot - Copy\connectors\meta_trader_5.py", line 207, in close_market_order_by_order_of_open
    pertinent_date = dates[order]
IndexError: list index out of range
ERROR:telethon.client.updates:Unhandled exception on handler
Traceback (most recent call last):
  File "C:\Users\caleb\OneDrive\Desktop\Dev Projects\Python Projects\trade_bot - Copy\venv\lib\site-packages\telethon\client\updates.py", line 467, in _dispatch_update
    await callback(event)
  File "C:\Users\caleb\OneDrive\Desktop\Dev Projects\Python Projects\trade_bot - Copy\run_bot.py", line 35, in handler
    blotter_message_json = blotter.trade_position(message_json)
  File "C:\Users\caleb\OneDrive\Desktop\Dev Projects\Python Projects\trade_bot - Copy\blotter\daily_blotter.py", line 56, in trade_position
    self.close_oldest_index_position()
  File "C:\Users\caleb\OneDrive\Desktop\Dev Projects\Python Projects\trade_bot - Copy\blotter\daily_blotter.py", line 138, in close_oldest_index_position
    symbol = self.INDEX_MAPPER[self.message_json['index']]['SYMBOL']
KeyError: None
ERROR:telethon.client.updates:Unhandled exception on handler
Traceback (most recent call last):
  File "C:\Users\caleb\OneDrive\Desktop\Dev Projects\Python Projects\trade_bot - Copy\venv\lib\site-packages\telethon\client\updates.py", line 467, in _dispatch_update
    await callback(event)
  File "C:\Users\caleb\OneDrive\Desktop\Dev Projects\Python Projects\trade_bot - Copy\run_bot.py", line 35, in handler
    blotter_message_json = blotter.trade_position(message_json)
  File "C:\Users\caleb\OneDrive\Desktop\Dev Projects\Python Projects\trade_bot - Copy\blotter\daily_blotter.py", line 56, in trade_position
    self.close_oldest_index_position()
  File "C:\Users\caleb\OneDrive\Desktop\Dev Projects\Python Projects\trade_bot - Copy\blotter\daily_blotter.py", line 138, in close_oldest_index_position
    symbol = self.INDEX_MAPPER[self.message_json['index']]['SYMBOL']
KeyError: None
ERROR:telethon.client.updates:Unhandled exception on handler
Traceback (most recent call last):
  File "C:\Users\caleb\OneDrive\Desktop\Dev Projects\Python Projects\trade_bot - Copy\venv\lib\site-packages\telethon\client\updates.py", line 467, in _dispatch_update
    await callback(event)
  File "C:\Users\caleb\OneDrive\Desktop\Dev Projects\Python Projects\trade_bot - Copy\run_bot.py", line 35, in handler
    blotter_message_json = blotter.trade_position(message_json)
  File "C:\Users\caleb\OneDrive\Desktop\Dev Projects\Python Projects\trade_bot - Copy\blotter\daily_blotter.py", line 56, in trade_position
    self.close_oldest_index_position()
  File "C:\Users\caleb\OneDrive\Desktop\Dev Projects\Python Projects\trade_bot - Copy\blotter\daily_blotter.py", line 138, in close_oldest_index_position
    symbol = self.INDEX_MAPPER[self.message_json['index']]['SYMBOL']
KeyError: None
ERROR:telethon.client.updates:Unhandled exception on handler
Traceback (most recent call last):
  File "C:\Users\caleb\OneDrive\Desktop\Dev Projects\Python Projects\trade_bot - Copy\venv\lib\site-packages\telethon\client\updates.py", line 467, in _dispatch_update
    await callback(event)
  File "C:\Users\caleb\OneDrive\Desktop\Dev Projects\Python Projects\trade_bot - Copy\run_bot.py", line 35, in handler
    blotter_message_json = blotter.trade_position(message_json)
  File "C:\Users\caleb\OneDrive\Desktop\Dev Projects\Python Projects\trade_bot - Copy\blotter\daily_blotter.py", line 56, in trade_position
    self.close_oldest_index_position()
  File "C:\Users\caleb\OneDrive\Desktop\Dev Projects\Python Projects\trade_bot - Copy\blotter\daily_blotter.py", line 138, in close_oldest_index_position
    symbol = self.INDEX_MAPPER[self.message_json['index']]['SYMBOL']
KeyError: None
ERROR:telethon.client.updates:Unhandled exception on handler
Traceback (most recent call last):
  File "C:\Users\caleb\OneDrive\Desktop\Dev Projects\Python Projects\trade_bot - Copy\venv\lib\site-packages\telethon\client\updates.py", line 467, in _dispatch_update
    await callback(event)
  File "C:\Users\caleb\OneDrive\Desktop\Dev Projects\Python Projects\trade_bot - Copy\run_bot.py", line 35, in handler
    blotter_message_json = blotter.trade_position(message_json)
  File "C:\Users\caleb\OneDrive\Desktop\Dev Projects\Python Projects\trade_bot - Copy\blotter\daily_blotter.py", line 56, in trade_position
    self.close_oldest_index_position()
  File "C:\Users\caleb\OneDrive\Desktop\Dev Projects\Python Projects\trade_bot - Copy\blotter\daily_blotter.py", line 138, in close_oldest_index_position
    symbol = self.INDEX_MAPPER[self.message_json['index']]['SYMBOL']
KeyError: None
ERROR:telethon.client.updates:Unhandled exception on handler
Traceback (most recent call last):
  File "C:\Users\caleb\OneDrive\Desktop\Dev Projects\Python Projects\trade_bot - Copy\venv\lib\site-packages\telethon\client\updates.py", line 467, in _dispatch_update
    await callback(event)
  File "C:\Users\caleb\OneDrive\Desktop\Dev Projects\Python Projects\trade_bot - Copy\run_bot.py", line 35, in handler
    blotter_message_json = blotter.trade_position(message_json)
  File "C:\Users\caleb\OneDrive\Desktop\Dev Projects\Python Projects\trade_bot - Copy\blotter\daily_blotter.py", line 53, in trade_position
    self.close_all_index_open_positions()
  File "C:\Users\caleb\OneDrive\Desktop\Dev Projects\Python Projects\trade_bot - Copy\blotter\daily_blotter.py", line 102, in close_all_index_open_positions
    messages = self.connector.close_all_positions_for_symbol(symbol = self.INDEX_MAPPER[self.message_json['index']]['SYMBOL'])
KeyError: None
ERROR:telethon.client.updates:Unhandled exception on handler
Traceback (most recent call last):
  File "C:\Users\caleb\OneDrive\Desktop\Dev Projects\Python Projects\trade_bot - Copy\venv\lib\site-packages\telethon\client\updates.py", line 467, in _dispatch_update
    await callback(event)
  File "C:\Users\caleb\OneDrive\Desktop\Dev Projects\Python Projects\trade_bot - Copy\run_bot.py", line 35, in handler
    blotter_message_json = blotter.trade_position(message_json)
  File "C:\Users\caleb\OneDrive\Desktop\Dev Projects\Python Projects\trade_bot - Copy\blotter\daily_blotter.py", line 53, in trade_position
    self.close_all_index_open_positions()
  File "C:\Users\caleb\OneDrive\Desktop\Dev Projects\Python Projects\trade_bot - Copy\blotter\daily_blotter.py", line 102, in close_all_index_open_positions
    messages = self.connector.close_all_positions_for_symbol(symbol = self.INDEX_MAPPER[self.message_json['index']]['SYMBOL'])
KeyError: None
ERROR:telethon.client.updates:Unhandled exception on handler
Traceback (most recent call last):
  File "C:\Users\caleb\OneDrive\Desktop\Dev Projects\Python Projects\trade_bot - Copy\venv\lib\site-packages\telethon\client\updates.py", line 467, in _dispatch_update
    await callback(event)
  File "C:\Users\caleb\OneDrive\Desktop\Dev Projects\Python Projects\trade_bot - Copy\run_bot.py", line 35, in handler
    blotter_message_json = blotter.trade_position(message_json)
  File "C:\Users\caleb\OneDrive\Desktop\Dev Projects\Python Projects\trade_bot - Copy\blotter\daily_blotter.py", line 53, in trade_position
    self.close_all_index_open_positions()
  File "C:\Users\caleb\OneDrive\Desktop\Dev Projects\Python Projects\trade_bot - Copy\blotter\daily_blotter.py", line 102, in close_all_index_open_positions
    messages = self.connector.close_all_positions_for_symbol(symbol = self.INDEX_MAPPER[self.message_json['index']]['SYMBOL'])
KeyError: None
ERROR:telethon.client.updates:Unhandled exception on handler
Traceback (most recent call last):
  File "C:\Users\caleb\OneDrive\Desktop\Dev Projects\Python Projects\trade_bot - Copy\venv\lib\site-packages\telethon\client\updates.py", line 467, in _dispatch_update
    await callback(event)
  File "C:\Users\caleb\OneDrive\Desktop\Dev Projects\Python Projects\trade_bot - Copy\run_bot.py", line 35, in handler
    blotter_message_json = blotter.trade_position(message_json)
  File "C:\Users\caleb\OneDrive\Desktop\Dev Projects\Python Projects\trade_bot - Copy\blotter\daily_blotter.py", line 53, in trade_position
    self.close_all_index_open_positions()
  File "C:\Users\caleb\OneDrive\Desktop\Dev Projects\Python Projects\trade_bot - Copy\blotter\daily_blotter.py", line 102, in close_all_index_open_positions
    messages = self.connector.close_all_positions_for_symbol(symbol = self.INDEX_MAPPER[self.message_json['index']]['SYMBOL'])
KeyError: None
ERROR:telethon.client.updates:Unhandled exception on handler
Traceback (most recent call last):
  File "C:\Users\caleb\OneDrive\Desktop\Dev Projects\Python Projects\trade_bot - Copy\venv\lib\site-packages\telethon\client\updates.py", line 467, in _dispatch_update
    await callback(event)
  File "C:\Users\caleb\OneDrive\Desktop\Dev Projects\Python Projects\trade_bot - Copy\run_bot.py", line 35, in handler
    blotter_message_json = blotter.trade_position(message_json)
  File "C:\Users\caleb\OneDrive\Desktop\Dev Projects\Python Projects\trade_bot - Copy\blotter\daily_blotter.py", line 56, in trade_position
    self.close_oldest_index_position()
  File "C:\Users\caleb\OneDrive\Desktop\Dev Projects\Python Projects\trade_bot - Copy\blotter\daily_blotter.py", line 138, in close_oldest_index_position
    symbol = self.INDEX_MAPPER[self.message_json['index']]['SYMBOL']
KeyError: None
ERROR:telethon.client.updates:Unhandled exception on handler
Traceback (most recent call last):
  File "C:\Users\caleb\OneDrive\Desktop\Dev Projects\Python Projects\trade_bot - Copy\venv\lib\site-packages\telethon\client\updates.py", line 467, in _dispatch_update
    await callback(event)
  File "C:\Users\caleb\OneDrive\Desktop\Dev Projects\Python Projects\trade_bot - Copy\run_bot.py", line 35, in handler
    blotter_message_json = blotter.trade_position(message_json)
  File "C:\Users\caleb\OneDrive\Desktop\Dev Projects\Python Projects\trade_bot - Copy\blotter\daily_blotter.py", line 56, in trade_position
    self.close_oldest_index_position()
  File "C:\Users\caleb\OneDrive\Desktop\Dev Projects\Python Projects\trade_bot - Copy\blotter\daily_blotter.py", line 138, in close_oldest_index_position
    symbol = self.INDEX_MAPPER[self.message_json['index']]['SYMBOL']
KeyError: None
ERROR:telethon.client.updates:Unhandled exception on handler
Traceback (most recent call last):
  File "C:\Users\caleb\OneDrive\Desktop\Dev Projects\Python Projects\trade_bot - Copy\venv\lib\site-packages\telethon\client\updates.py", line 467, in _dispatch_update
    await callback(event)
  File "C:\Users\caleb\OneDrive\Desktop\Dev Projects\Python Projects\trade_bot - Copy\run_bot.py", line 35, in handler
    blotter_message_json = blotter.trade_position(message_json)
  File "C:\Users\caleb\OneDrive\Desktop\Dev Projects\Python Projects\trade_bot - Copy\blotter\daily_blotter.py", line 56, in trade_position
    self.close_oldest_index_position()
  File "C:\Users\caleb\OneDrive\Desktop\Dev Projects\Python Projects\trade_bot - Copy\blotter\daily_blotter.py", line 138, in close_oldest_index_position
    symbol = self.INDEX_MAPPER[self.message_json['index']]['SYMBOL']
KeyError: None
ERROR:telethon.client.updates:Unhandled exception on handler
Traceback (most recent call last):
  File "C:\Users\caleb\OneDrive\Desktop\Dev Projects\Python Projects\trade_bot - Copy\venv\lib\site-packages\telethon\client\updates.py", line 467, in _dispatch_update
    await callback(event)
  File "C:\Users\caleb\OneDrive\Desktop\Dev Projects\Python Projects\trade_bot - Copy\run_bot.py", line 35, in handler
    blotter_message_json = blotter.trade_position(message_json)
  File "C:\Users\caleb\OneDrive\Desktop\Dev Projects\Python Projects\trade_bot - Copy\blotter\daily_blotter.py", line 56, in trade_position
    self.close_oldest_index_position()
  File "C:\Users\caleb\OneDrive\Desktop\Dev Projects\Python Projects\trade_bot - Copy\blotter\daily_blotter.py", line 138, in close_oldest_index_position
    symbol = self.INDEX_MAPPER[self.message_json['index']]['SYMBOL']
KeyError: None
ERROR:telethon.client.updates:Unhandled exception on handler
Traceback (most recent call last):
  File "C:\Users\caleb\OneDrive\Desktop\Dev Projects\Python Projects\trade_bot - Copy\venv\lib\site-packages\telethon\client\updates.py", line 467, in _dispatch_update
    await callback(event)
  File "C:\Users\caleb\OneDrive\Desktop\Dev Projects\Python Projects\trade_bot - Copy\run_bot.py", line 35, in handler
    blotter_message_json = blotter.trade_position(message_json)
  File "C:\Users\caleb\OneDrive\Desktop\Dev Projects\Python Projects\trade_bot - Copy\blotter\daily_blotter.py", line 56, in trade_position
    self.close_oldest_index_position()
  File "C:\Users\caleb\OneDrive\Desktop\Dev Projects\Python Projects\trade_bot - Copy\blotter\daily_blotter.py", line 138, in close_oldest_index_position
    symbol = self.INDEX_MAPPER[self.message_json['index']]['SYMBOL']
KeyError: None
ERROR:asyncio:Task exception was never retrieved
future: <Task finished name='Task-17' coro=<UpdateMethods._dispatch_update() done, defined at C:\Users\caleb\OneDrive\Desktop\Dev Projects\Python Projects\trade_bot - Copy\venv\lib\site-packages\telethon\client\updates.py:399> exception=KeyboardInterrupt()>
Traceback (most recent call last):
  File "C:\Users\caleb\OneDrive\Desktop\Dev Projects\Python Projects\trade_bot - Copy\venv\lib\site-packages\telethon\client\updates.py", line 84, in run_until_disconnected
    return self.loop.run_until_complete(self._run_until_disconnected())
  File "C:\Users\caleb\AppData\Local\Programs\Python\Python39\lib\asyncio\base_events.py", line 629, in run_until_complete
    self.run_forever()
  File "C:\Users\caleb\AppData\Local\Programs\Python\Python39\lib\asyncio\windows_events.py", line 316, in run_forever
    super().run_forever()
  File "C:\Users\caleb\AppData\Local\Programs\Python\Python39\lib\asyncio\base_events.py", line 596, in run_forever
    self._run_once()
  File "C:\Users\caleb\AppData\Local\Programs\Python\Python39\lib\asyncio\base_events.py", line 1890, in _run_once
    handle._run()
  File "C:\Users\caleb\AppData\Local\Programs\Python\Python39\lib\asyncio\events.py", line 80, in _run
    self._context.run(self._callback, *self._args)
  File "C:\Users\caleb\OneDrive\Desktop\Dev Projects\Python Projects\trade_bot - Copy\venv\lib\site-packages\telethon\client\updates.py", line 467, in _dispatch_update
    await callback(event)
  File "C:\Users\caleb\OneDrive\Desktop\Dev Projects\Python Projects\trade_bot - Copy\run_bot.py", line 35, in handler
    blotter_message_json = blotter.trade_position(message_json)
  File "C:\Users\caleb\OneDrive\Desktop\Dev Projects\Python Projects\trade_bot - Copy\run_bot.py", line 35, in handler
    blotter_message_json = blotter.trade_position(message_json)
  File "_pydevd_bundle\pydevd_cython_win32_39_64.pyx", line 1589, in _pydevd_bundle.pydevd_cython_win32_39_64.ThreadTracer.__call__
  File "_pydevd_bundle\pydevd_cython_win32_39_64.pyx", line 929, in _pydevd_bundle.pydevd_cython_win32_39_64.PyDBFrame.trace_dispatch
  File "_pydevd_bundle\pydevd_cython_win32_39_64.pyx", line 920, in _pydevd_bundle.pydevd_cython_win32_39_64.PyDBFrame.trace_dispatch
  File "_pydevd_bundle\pydevd_cython_win32_39_64.pyx", line 317, in _pydevd_bundle.pydevd_cython_win32_39_64.PyDBFrame.do_wait_suspend
  File "C:\Program Files\JetBrains\PyCharm Community Edition 2021.2.3\plugins\python-ce\helpers\pydev\pydevd.py", line 1147, in do_wait_suspend
    self._do_wait_suspend(thread, frame, event, arg, suspend_type, from_this_thread)
  File "C:\Program Files\JetBrains\PyCharm Community Edition 2021.2.3\plugins\python-ce\helpers\pydev\pydevd.py", line 1162, in _do_wait_suspend
    time.sleep(0.01)
KeyboardInterrupt
ERROR:asyncio:Task exception was never retrieved
future: <Task finished name='Task-8' coro=<UpdateMethods._run_until_disconnected() done, defined at C:\Users\caleb\OneDrive\Desktop\Dev Projects\Python Projects\trade_bot - Copy\venv\lib\site-packages\telethon\client\updates.py:25> exception=OperationalError('database is locked')>
Traceback (most recent call last):
  File "C:\Users\caleb\OneDrive\Desktop\Dev Projects\Python Projects\trade_bot - Copy\venv\lib\site-packages\telethon\client\updates.py", line 33, in _run_until_disconnected
    await self.disconnect()
  File "C:\Users\caleb\OneDrive\Desktop\Dev Projects\Python Projects\trade_bot - Copy\venv\lib\site-packages\telethon\client\telegrambaseclient.py", line 647, in _disconnect_coro
    self.session.set_update_state(0, types.updates.State(
  File "C:\Users\caleb\OneDrive\Desktop\Dev Projects\Python Projects\trade_bot - Copy\venv\lib\site-packages\telethon\sessions\sqlite.py", line 214, in set_update_state
    self._execute('insert or replace into update_state values (?,?,?,?,?)',
  File "C:\Users\caleb\OneDrive\Desktop\Dev Projects\Python Projects\trade_bot - Copy\venv\lib\site-packages\telethon\sessions\sqlite.py", line 239, in _execute
    return c.execute(stmt, values).fetchone()
sqlite3.OperationalError: database is locked
ERROR:telethon.client.updates:Unhandled exception on handler
Traceback (most recent call last):
  File "C:\Users\caleb\OneDrive\Desktop\Dev Projects\Python Projects\trade_bot - Copy\venv\lib\site-packages\telethon\client\updates.py", line 467, in _dispatch_update
    await callback(event)
  File "C:\Users\caleb\OneDrive\Desktop\Dev Projects\Python Projects\trade_bot - Copy\run_bot.py", line 35, in handler
    blotter_message_json = blotter.trade_position(message_json)
  File "C:\Users\caleb\OneDrive\Desktop\Dev Projects\Python Projects\trade_bot - Copy\blotter\daily_blotter.py", line 56, in trade_position
    self.close_oldest_index_position()
  File "C:\Users\caleb\OneDrive\Desktop\Dev Projects\Python Projects\trade_bot - Copy\blotter\daily_blotter.py", line 139, in close_oldest_index_position
    confirmation = self.connector.close_market_order_by_order_of_open(symbol = symbol, first = True)
  File "C:\Users\caleb\OneDrive\Desktop\Dev Projects\Python Projects\trade_bot - Copy\connectors\meta_trader_5.py", line 207, in close_market_order_by_order_of_open
    pertinent_date = dates[order]
IndexError: list index out of range
ERROR:asyncio:Task exception was never retrieved
future: <Task finished name='Task-12' coro=<UpdateMethods._dispatch_update() done, defined at C:\Users\caleb\OneDrive\Desktop\Dev Projects\Python Projects\trade_bot - Copy\venv\lib\site-packages\telethon\client\updates.py:399> exception=KeyboardInterrupt()>
Traceback (most recent call last):
  File "C:\Users\caleb\OneDrive\Desktop\Dev Projects\Python Projects\trade_bot - Copy\venv\lib\site-packages\telethon\client\updates.py", line 84, in run_until_disconnected
    return self.loop.run_until_complete(self._run_until_disconnected())
  File "C:\Users\caleb\AppData\Local\Programs\Python\Python39\lib\asyncio\base_events.py", line 629, in run_until_complete
    self.run_forever()
  File "C:\Users\caleb\AppData\Local\Programs\Python\Python39\lib\asyncio\windows_events.py", line 316, in run_forever
    super().run_forever()
  File "C:\Users\caleb\AppData\Local\Programs\Python\Python39\lib\asyncio\base_events.py", line 596, in run_forever
    self._run_once()
  File "C:\Users\caleb\AppData\Local\Programs\Python\Python39\lib\asyncio\base_events.py", line 1890, in _run_once
    handle._run()
  File "C:\Users\caleb\AppData\Local\Programs\Python\Python39\lib\asyncio\events.py", line 80, in _run
    self._context.run(self._callback, *self._args)
  File "C:\Users\caleb\OneDrive\Desktop\Dev Projects\Python Projects\trade_bot - Copy\venv\lib\site-packages\telethon\client\updates.py", line 467, in _dispatch_update
    await callback(event)
  File "C:\Users\caleb\OneDrive\Desktop\Dev Projects\Python Projects\trade_bot - Copy\run_bot.py", line 31, in handler
    message_json = message_parser.get_trade_info(input_text, edited_message=isinstance(event,
  File "C:\Users\caleb\OneDrive\Desktop\Dev Projects\Python Projects\trade_bot - Copy\message_parser\text_parser.py", line 24, in get_trade_info
    self.text_list = self.text_input.split('\n')
  File "C:\Users\caleb\OneDrive\Desktop\Dev Projects\Python Projects\trade_bot - Copy\message_parser\text_parser.py", line 24, in get_trade_info
    self.text_list = self.text_input.split('\n')
  File "_pydevd_bundle\pydevd_cython_win32_39_64.pyx", line 1179, in _pydevd_bundle.pydevd_cython_win32_39_64.SafeCallWrapper.__call__
  File "_pydevd_bundle\pydevd_cython_win32_39_64.pyx", line 620, in _pydevd_bundle.pydevd_cython_win32_39_64.PyDBFrame.trace_dispatch
  File "_pydevd_bundle\pydevd_cython_win32_39_64.pyx", line 1095, in _pydevd_bundle.pydevd_cython_win32_39_64.PyDBFrame.trace_dispatch
  File "_pydevd_bundle\pydevd_cython_win32_39_64.pyx", line 1057, in _pydevd_bundle.pydevd_cython_win32_39_64.PyDBFrame.trace_dispatch
  File "_pydevd_bundle\pydevd_cython_win32_39_64.pyx", line 317, in _pydevd_bundle.pydevd_cython_win32_39_64.PyDBFrame.do_wait_suspend
  File "C:\Program Files\JetBrains\PyCharm Community Edition 2021.2.3\plugins\python-ce\helpers\pydev\pydevd.py", line 1147, in do_wait_suspend
    self._do_wait_suspend(thread, frame, event, arg, suspend_type, from_this_thread)
  File "C:\Program Files\JetBrains\PyCharm Community Edition 2021.2.3\plugins\python-ce\helpers\pydev\pydevd.py", line 1162, in _do_wait_suspend
    time.sleep(0.01)
KeyboardInterrupt
ERROR:telethon.client.updates:Unhandled exception on handler
Traceback (most recent call last):
  File "C:\Users\caleb\OneDrive\Desktop\Dev Projects\Python Projects\trade_bot - Copy\venv\lib\site-packages\telethon\client\updates.py", line 467, in _dispatch_update
    await callback(event)
  File "C:\Users\caleb\OneDrive\Desktop\Dev Projects\Python Projects\trade_bot - Copy\run_bot.py", line 35, in handler
    blotter_message_json = blotter.trade_position(message_json)
  File "C:\Users\caleb\OneDrive\Desktop\Dev Projects\Python Projects\trade_bot - Copy\blotter\daily_blotter.py", line 56, in trade_position
    self.close_oldest_index_position()
  File "C:\Users\caleb\OneDrive\Desktop\Dev Projects\Python Projects\trade_bot - Copy\blotter\daily_blotter.py", line 138, in close_oldest_index_position
    symbol = self.INDEX_MAPPER[self.message_json['index']]['SYMBOL']
KeyError: None
ERROR:telethon.client.updates:Unhandled exception on handler
Traceback (most recent call last):
  File "C:\Users\caleb\OneDrive\Desktop\Dev Projects\Python Projects\trade_bot - Copy\venv\lib\site-packages\telethon\client\updates.py", line 467, in _dispatch_update
    await callback(event)
  File "C:\Users\caleb\OneDrive\Desktop\Dev Projects\Python Projects\trade_bot - Copy\run_bot.py", line 35, in handler
    blotter_message_json = blotter.trade_position(message_json)
  File "C:\Users\caleb\OneDrive\Desktop\Dev Projects\Python Projects\trade_bot - Copy\blotter\daily_blotter.py", line 56, in trade_position
    self.close_oldest_index_position()
  File "C:\Users\caleb\OneDrive\Desktop\Dev Projects\Python Projects\trade_bot - Copy\blotter\daily_blotter.py", line 139, in close_oldest_index_position
    confirmation = self.connector.close_market_order_by_order_of_open(symbol = symbol, first = True)
  File "C:\Users\caleb\OneDrive\Desktop\Dev Projects\Python Projects\trade_bot - Copy\connectors\meta_trader_5.py", line 207, in close_market_order_by_order_of_open
    pertinent_date = dates[order]
IndexError: list index out of range
ERROR:telethon.client.updates:Unhandled exception on handler
Traceback (most recent call last):
  File "C:\Users\caleb\OneDrive\Desktop\Dev Projects\Python Projects\trade_bot - Copy\venv\lib\site-packages\telethon\client\updates.py", line 467, in _dispatch_update
    await callback(event)
  File "C:\Users\caleb\OneDrive\Desktop\Dev Projects\Python Projects\trade_bot - Copy\run_bot.py", line 35, in handler
    blotter_message_json = blotter.trade_position(message_json)
  File "C:\Users\caleb\OneDrive\Desktop\Dev Projects\Python Projects\trade_bot - Copy\blotter\daily_blotter.py", line 56, in trade_position
    self.close_oldest_index_position()
  File "C:\Users\caleb\OneDrive\Desktop\Dev Projects\Python Projects\trade_bot - Copy\blotter\daily_blotter.py", line 139, in close_oldest_index_position
    confirmation = self.connector.close_market_order_by_order_of_open(symbol = symbol, first = True)
  File "C:\Users\caleb\OneDrive\Desktop\Dev Projects\Python Projects\trade_bot - Copy\connectors\meta_trader_5.py", line 207, in close_market_order_by_order_of_open
    pertinent_date = dates[order]
IndexError: list index out of range
ERROR:telethon.client.updates:Unhandled exception on handler
Traceback (most recent call last):
  File "C:\Users\caleb\OneDrive\Desktop\Dev Projects\Python Projects\trade_bot - Copy\venv\lib\site-packages\telethon\client\updates.py", line 467, in _dispatch_update
    await callback(event)
  File "C:\Users\caleb\OneDrive\Desktop\Dev Projects\Python Projects\trade_bot - Copy\run_bot.py", line 35, in handler
    blotter_message_json = blotter.trade_position(message_json)
  File "C:\Users\caleb\OneDrive\Desktop\Dev Projects\Python Projects\trade_bot - Copy\blotter\daily_blotter.py", line 56, in trade_position
    self.close_oldest_index_position()
  File "C:\Users\caleb\OneDrive\Desktop\Dev Projects\Python Projects\trade_bot - Copy\blotter\daily_blotter.py", line 139, in close_oldest_index_position
    confirmation = self.connector.close_market_order_by_order_of_open(symbol = symbol, first = True)
  File "C:\Users\caleb\OneDrive\Desktop\Dev Projects\Python Projects\trade_bot - Copy\connectors\meta_trader_5.py", line 207, in close_market_order_by_order_of_open
    pertinent_date = dates[order]
IndexError: list index out of range
ERROR:telethon.client.updates:Unhandled exception on handler
Traceback (most recent call last):
  File "C:\Users\caleb\OneDrive\Desktop\Dev Projects\Python Projects\trade_bot - Copy\venv\lib\site-packages\telethon\client\updates.py", line 467, in _dispatch_update
    await callback(event)
  File "C:\Users\caleb\OneDrive\Desktop\Dev Projects\Python Projects\trade_bot - Copy\run_bot.py", line 35, in handler
    blotter_message_json = blotter.trade_position(message_json)
  File "C:\Users\caleb\OneDrive\Desktop\Dev Projects\Python Projects\trade_bot - Copy\blotter\daily_blotter.py", line 56, in trade_position
    self.close_oldest_index_position()
  File "C:\Users\caleb\OneDrive\Desktop\Dev Projects\Python Projects\trade_bot - Copy\blotter\daily_blotter.py", line 139, in close_oldest_index_position
    confirmation = self.connector.close_market_order_by_order_of_open(symbol = symbol, first = True)
  File "C:\Users\caleb\OneDrive\Desktop\Dev Projects\Python Projects\trade_bot - Copy\connectors\meta_trader_5.py", line 207, in close_market_order_by_order_of_open
    pertinent_date = dates[order]
IndexError: list index out of range
ERROR:asyncio:Task exception was never retrieved
future: <Task finished name='Task-16' coro=<UpdateMethods._dispatch_update() done, defined at C:\Users\caleb\OneDrive\Desktop\Dev Projects\Python Projects\trade_bot - Copy\venv\lib\site-packages\telethon\client\updates.py:399> exception=KeyboardInterrupt()>
Traceback (most recent call last):
  File "C:\Users\caleb\OneDrive\Desktop\Dev Projects\Python Projects\trade_bot - Copy\venv\lib\site-packages\telethon\client\updates.py", line 84, in run_until_disconnected
    return self.loop.run_until_complete(self._run_until_disconnected())
  File "C:\Users\caleb\AppData\Local\Programs\Python\Python39\lib\asyncio\base_events.py", line 629, in run_until_complete
    self.run_forever()
  File "C:\Users\caleb\AppData\Local\Programs\Python\Python39\lib\asyncio\windows_events.py", line 316, in run_forever
    super().run_forever()
  File "C:\Users\caleb\AppData\Local\Programs\Python\Python39\lib\asyncio\base_events.py", line 596, in run_forever
    self._run_once()
  File "C:\Users\caleb\AppData\Local\Programs\Python\Python39\lib\asyncio\base_events.py", line 1890, in _run_once
    handle._run()
  File "C:\Users\caleb\AppData\Local\Programs\Python\Python39\lib\asyncio\events.py", line 80, in _run
    self._context.run(self._callback, *self._args)
  File "C:\Users\caleb\OneDrive\Desktop\Dev Projects\Python Projects\trade_bot - Copy\venv\lib\site-packages\telethon\client\updates.py", line 467, in _dispatch_update
    await callback(event)
  File "C:\Users\caleb\OneDrive\Desktop\Dev Projects\Python Projects\trade_bot - Copy\run_bot.py", line 35, in handler
    blotter_message_json = blotter.trade_position(message_json)
  File "C:\Users\caleb\OneDrive\Desktop\Dev Projects\Python Projects\trade_bot - Copy\run_bot.py", line 35, in handler
    blotter_message_json = blotter.trade_position(message_json)
  File "_pydevd_bundle\pydevd_cython_win32_39_64.pyx", line 1589, in _pydevd_bundle.pydevd_cython_win32_39_64.ThreadTracer.__call__
  File "_pydevd_bundle\pydevd_cython_win32_39_64.pyx", line 929, in _pydevd_bundle.pydevd_cython_win32_39_64.PyDBFrame.trace_dispatch
  File "_pydevd_bundle\pydevd_cython_win32_39_64.pyx", line 920, in _pydevd_bundle.pydevd_cython_win32_39_64.PyDBFrame.trace_dispatch
  File "_pydevd_bundle\pydevd_cython_win32_39_64.pyx", line 317, in _pydevd_bundle.pydevd_cython_win32_39_64.PyDBFrame.do_wait_suspend
  File "C:\Program Files\JetBrains\PyCharm Community Edition 2021.2.3\plugins\python-ce\helpers\pydev\pydevd.py", line 1147, in do_wait_suspend
    self._do_wait_suspend(thread, frame, event, arg, suspend_type, from_this_thread)
  File "C:\Program Files\JetBrains\PyCharm Community Edition 2021.2.3\plugins\python-ce\helpers\pydev\pydevd.py", line 1161, in _do_wait_suspend
    self.process_internal_commands()
  File "C:\Program Files\JetBrains\PyCharm Community Edition 2021.2.3\plugins\python-ce\helpers\pydev\pydevd.py", line 821, in process_internal_commands
    self.notify_thread_created(thread_id, t, use_lock=False)
  File "C:\Program Files\JetBrains\PyCharm Community Edition 2021.2.3\plugins\python-ce\helpers\pydev\pydevd.py", line 753, in notify_thread_created
    with self._lock_running_thread_ids if use_lock else NULL:
KeyboardInterrupt
ERROR:asyncio:Task exception was never retrieved
future: <Task finished name='Task-11' coro=<UpdateMethods._dispatch_update() done, defined at C:\Users\caleb\OneDrive\Desktop\Dev Projects\Python Projects\trade_bot - Copy\venv\lib\site-packages\telethon\client\updates.py:399> exception=KeyboardInterrupt()>
Traceback (most recent call last):
  File "C:\Users\caleb\OneDrive\Desktop\Dev Projects\Python Projects\trade_bot - Copy\venv\lib\site-packages\telethon\client\updates.py", line 84, in run_until_disconnected
    return self.loop.run_until_complete(self._run_until_disconnected())
  File "C:\Users\caleb\AppData\Local\Programs\Python\Python39\lib\asyncio\base_events.py", line 629, in run_until_complete
    self.run_forever()
  File "C:\Users\caleb\AppData\Local\Programs\Python\Python39\lib\asyncio\windows_events.py", line 316, in run_forever
    super().run_forever()
  File "C:\Users\caleb\AppData\Local\Programs\Python\Python39\lib\asyncio\base_events.py", line 596, in run_forever
    self._run_once()
  File "C:\Users\caleb\AppData\Local\Programs\Python\Python39\lib\asyncio\base_events.py", line 1890, in _run_once
    handle._run()
  File "C:\Users\caleb\AppData\Local\Programs\Python\Python39\lib\asyncio\events.py", line 80, in _run
    self._context.run(self._callback, *self._args)
  File "C:\Users\caleb\OneDrive\Desktop\Dev Projects\Python Projects\trade_bot - Copy\venv\lib\site-packages\telethon\client\updates.py", line 467, in _dispatch_update
    await callback(event)
  File "C:\Users\caleb\OneDrive\Desktop\Dev Projects\Python Projects\trade_bot - Copy\run_bot.py", line 35, in handler
    blotter_message_json = blotter.trade_position(message_json)
  File "C:\Users\caleb\OneDrive\Desktop\Dev Projects\Python Projects\trade_bot - Copy\run_bot.py", line 35, in handler
    blotter_message_json = blotter.trade_position(message_json)
  File "_pydevd_bundle\pydevd_cython_win32_39_64.pyx", line 1589, in _pydevd_bundle.pydevd_cython_win32_39_64.ThreadTracer.__call__
  File "_pydevd_bundle\pydevd_cython_win32_39_64.pyx", line 929, in _pydevd_bundle.pydevd_cython_win32_39_64.PyDBFrame.trace_dispatch
  File "_pydevd_bundle\pydevd_cython_win32_39_64.pyx", line 920, in _pydevd_bundle.pydevd_cython_win32_39_64.PyDBFrame.trace_dispatch
  File "_pydevd_bundle\pydevd_cython_win32_39_64.pyx", line 317, in _pydevd_bundle.pydevd_cython_win32_39_64.PyDBFrame.do_wait_suspend
  File "C:\Program Files\JetBrains\PyCharm Community Edition 2021.2.3\plugins\python-ce\helpers\pydev\pydevd.py", line 1147, in do_wait_suspend
    self._do_wait_suspend(thread, frame, event, arg, suspend_type, from_this_thread)
  File "C:\Program Files\JetBrains\PyCharm Community Edition 2021.2.3\plugins\python-ce\helpers\pydev\pydevd.py", line 1162, in _do_wait_suspend
    time.sleep(0.01)
KeyboardInterrupt
ERROR:telethon.client.updates:Unhandled exception on handler
Traceback (most recent call last):
  File "C:\Users\caleb\OneDrive\Desktop\Dev Projects\Python Projects\trade_bot - Copy\venv\lib\site-packages\telethon\client\updates.py", line 467, in _dispatch_update
    await callback(event)
  File "C:\Users\caleb\OneDrive\Desktop\Dev Projects\Python Projects\trade_bot - Copy\run_bot.py", line 31, in handler
    message_json = message_parser.get_trade_info(input_text, edited_message=isinstance(event,
  File "C:\Users\caleb\OneDrive\Desktop\Dev Projects\Python Projects\trade_bot - Copy\message_parser\text_parser.py", line 32, in get_trade_info
    return self.parse_message()
  File "C:\Users\caleb\OneDrive\Desktop\Dev Projects\Python Projects\trade_bot - Copy\message_parser\text_parser.py", line 45, in parse_message
    self.parse_open_trade_message()
  File "C:\Users\caleb\OneDrive\Desktop\Dev Projects\Python Projects\trade_bot - Copy\message_parser\text_parser.py", line 62, in parse_open_trade_message
    self.parse_index_name()
  File "C:\Users\caleb\OneDrive\Desktop\Dev Projects\Python Projects\trade_bot - Copy\message_parser\text_parser.py", line 154, in parse_index_name
    self.RESULT.update(self.get_index_from_string(index_string))
  File "C:\Users\caleb\OneDrive\Desktop\Dev Projects\Python Projects\trade_bot - Copy\message_parser\text_parser.py", line 195, in get_index_from_string
    if any(option in string for option in self.INDEX_MAPPER[key]["OPTIONS"]) or string == key:
KeyError: 'OPTIONS'
ERROR:telethon.client.updates:Unhandled exception on handler
Traceback (most recent call last):
  File "C:\Users\caleb\OneDrive\Desktop\Dev Projects\Python Projects\trade_bot - Copy\venv\lib\site-packages\telethon\client\updates.py", line 467, in _dispatch_update
    await callback(event)
  File "C:\Users\caleb\OneDrive\Desktop\Dev Projects\Python Projects\trade_bot - Copy\run_bot.py", line 31, in handler
    message_json = message_parser.get_trade_info(input_text, edited_message=isinstance(event,
  File "C:\Users\caleb\OneDrive\Desktop\Dev Projects\Python Projects\trade_bot - Copy\message_parser\text_parser.py", line 32, in get_trade_info
    return self.parse_message()
  File "C:\Users\caleb\OneDrive\Desktop\Dev Projects\Python Projects\trade_bot - Copy\message_parser\text_parser.py", line 45, in parse_message
    self.parse_open_trade_message()
  File "C:\Users\caleb\OneDrive\Desktop\Dev Projects\Python Projects\trade_bot - Copy\message_parser\text_parser.py", line 62, in parse_open_trade_message
    self.parse_index_name()
  File "C:\Users\caleb\OneDrive\Desktop\Dev Projects\Python Projects\trade_bot - Copy\message_parser\text_parser.py", line 154, in parse_index_name
    self.RESULT.update(self.get_index_from_string(index_string))
  File "C:\Users\caleb\OneDrive\Desktop\Dev Projects\Python Projects\trade_bot - Copy\message_parser\text_parser.py", line 195, in get_index_from_string
    if any(option in string for option in self.INDEX_MAPPER[key]["OPTIONS"]) or string == key:
KeyError: 'OPTIONS'
ERROR:telethon.client.updates:Unhandled exception on handler
Traceback (most recent call last):
  File "C:\Users\caleb\OneDrive\Desktop\Dev Projects\Python Projects\trade_bot - Copy\venv\lib\site-packages\telethon\client\updates.py", line 467, in _dispatch_update
    await callback(event)
  File "C:\Users\caleb\OneDrive\Desktop\Dev Projects\Python Projects\trade_bot - Copy\run_bot.py", line 31, in handler
    message_json = message_parser.get_trade_info(input_text, edited_message=isinstance(event,
  File "C:\Users\caleb\OneDrive\Desktop\Dev Projects\Python Projects\trade_bot - Copy\message_parser\text_parser.py", line 32, in get_trade_info
    return self.parse_message()
  File "C:\Users\caleb\OneDrive\Desktop\Dev Projects\Python Projects\trade_bot - Copy\message_parser\text_parser.py", line 45, in parse_message
    self.parse_open_trade_message()
  File "C:\Users\caleb\OneDrive\Desktop\Dev Projects\Python Projects\trade_bot - Copy\message_parser\text_parser.py", line 62, in parse_open_trade_message
    self.parse_index_name()
  File "C:\Users\caleb\OneDrive\Desktop\Dev Projects\Python Projects\trade_bot - Copy\message_parser\text_parser.py", line 154, in parse_index_name
    self.RESULT.update(self.get_index_from_string(index_string))
  File "C:\Users\caleb\OneDrive\Desktop\Dev Projects\Python Projects\trade_bot - Copy\message_parser\text_parser.py", line 195, in get_index_from_string
    if any(option in string for option in self.INDEX_MAPPER[key]["OPTIONS"]) or string == key:
KeyError: 'OPTIONS'
ERROR:telethon.client.updates:Unhandled exception on handler
Traceback (most recent call last):
  File "C:\Users\caleb\OneDrive\Desktop\Dev Projects\Python Projects\trade_bot - Copy\venv\lib\site-packages\telethon\client\updates.py", line 467, in _dispatch_update
    await callback(event)
  File "C:\Users\caleb\OneDrive\Desktop\Dev Projects\Python Projects\trade_bot - Copy\run_bot.py", line 31, in handler
    message_json = message_parser.get_trade_info(input_text, edited_message=isinstance(event,
  File "C:\Users\caleb\OneDrive\Desktop\Dev Projects\Python Projects\trade_bot - Copy\message_parser\text_parser.py", line 32, in get_trade_info
    return self.parse_message()
  File "C:\Users\caleb\OneDrive\Desktop\Dev Projects\Python Projects\trade_bot - Copy\message_parser\text_parser.py", line 45, in parse_message
    self.parse_open_trade_message()
  File "C:\Users\caleb\OneDrive\Desktop\Dev Projects\Python Projects\trade_bot - Copy\message_parser\text_parser.py", line 62, in parse_open_trade_message
    self.parse_index_name()
  File "C:\Users\caleb\OneDrive\Desktop\Dev Projects\Python Projects\trade_bot - Copy\message_parser\text_parser.py", line 154, in parse_index_name
    self.RESULT.update(self.get_index_from_string(index_string))
  File "C:\Users\caleb\OneDrive\Desktop\Dev Projects\Python Projects\trade_bot - Copy\message_parser\text_parser.py", line 195, in get_index_from_string
    if any(option in string for option in self.INDEX_MAPPER[key]["OPTIONS"]) or string == key:
KeyError: 'OPTIONS'
ERROR:telethon.client.updates:Unhandled exception on handler
Traceback (most recent call last):
  File "C:\Users\caleb\OneDrive\Desktop\Dev Projects\Python Projects\trade_bot - Copy\venv\lib\site-packages\telethon\client\updates.py", line 467, in _dispatch_update
    await callback(event)
  File "C:\Users\caleb\OneDrive\Desktop\Dev Projects\Python Projects\trade_bot - Copy\run_bot.py", line 31, in handler
    message_json = message_parser.get_trade_info(input_text, edited_message=isinstance(event,
  File "C:\Users\caleb\OneDrive\Desktop\Dev Projects\Python Projects\trade_bot - Copy\message_parser\text_parser.py", line 32, in get_trade_info
    return self.parse_message()
  File "C:\Users\caleb\OneDrive\Desktop\Dev Projects\Python Projects\trade_bot - Copy\message_parser\text_parser.py", line 45, in parse_message
    self.parse_open_trade_message()
  File "C:\Users\caleb\OneDrive\Desktop\Dev Projects\Python Projects\trade_bot - Copy\message_parser\text_parser.py", line 62, in parse_open_trade_message
    self.parse_index_name()
  File "C:\Users\caleb\OneDrive\Desktop\Dev Projects\Python Projects\trade_bot - Copy\message_parser\text_parser.py", line 154, in parse_index_name
    self.RESULT.update(self.get_index_from_string(index_string))
  File "C:\Users\caleb\OneDrive\Desktop\Dev Projects\Python Projects\trade_bot - Copy\message_parser\text_parser.py", line 195, in get_index_from_string
    if any(option in string for option in self.INDEX_MAPPER[key]["OPTIONS"]) or string == key:
KeyError: 'OPTIONS'
ERROR:asyncio:Task exception was never retrieved
future: <Task finished name='Task-20' coro=<UpdateMethods._dispatch_update() done, defined at C:\Users\caleb\OneDrive\Desktop\Dev Projects\Python Projects\trade_bot - Copy\venv\lib\site-packages\telethon\client\updates.py:399> exception=KeyboardInterrupt()>
Traceback (most recent call last):
  File "C:\Users\caleb\OneDrive\Desktop\Dev Projects\Python Projects\trade_bot - Copy\venv\lib\site-packages\telethon\client\updates.py", line 84, in run_until_disconnected
    return self.loop.run_until_complete(self._run_until_disconnected())
  File "C:\Users\caleb\AppData\Local\Programs\Python\Python39\lib\asyncio\base_events.py", line 629, in run_until_complete
    self.run_forever()
  File "C:\Users\caleb\AppData\Local\Programs\Python\Python39\lib\asyncio\windows_events.py", line 316, in run_forever
    super().run_forever()
  File "C:\Users\caleb\AppData\Local\Programs\Python\Python39\lib\asyncio\base_events.py", line 596, in run_forever
    self._run_once()
  File "C:\Users\caleb\AppData\Local\Programs\Python\Python39\lib\asyncio\base_events.py", line 1890, in _run_once
    handle._run()
  File "C:\Users\caleb\AppData\Local\Programs\Python\Python39\lib\asyncio\events.py", line 80, in _run
    self._context.run(self._callback, *self._args)
  File "C:\Users\caleb\OneDrive\Desktop\Dev Projects\Python Projects\trade_bot - Copy\venv\lib\site-packages\telethon\client\updates.py", line 467, in _dispatch_update
    await callback(event)
  File "C:\Users\caleb\OneDrive\Desktop\Dev Projects\Python Projects\trade_bot - Copy\run_bot.py", line 31, in handler
    message_json = message_parser.get_trade_info(input_text, edited_message=isinstance(event,
  File "C:\Program Files\JetBrains\PyCharm Community Edition 2021.2.3\plugins\python-ce\helpers\pydev\_pydevd_bundle\pydevd_trace_dispatch.py", line 59, in trace_dispatch
    return _trace_dispatch(py_db, frame, event, arg)
  File "_pydevd_bundle\pydevd_cython_win32_39_64.pyx", line 1329, in _pydevd_bundle.pydevd_cython_win32_39_64.trace_dispatch
  File "_pydevd_bundle\pydevd_cython_win32_39_64.pyx", line 1589, in _pydevd_bundle.pydevd_cython_win32_39_64.ThreadTracer.__call__
  File "_pydevd_bundle\pydevd_cython_win32_39_64.pyx", line 929, in _pydevd_bundle.pydevd_cython_win32_39_64.PyDBFrame.trace_dispatch
  File "_pydevd_bundle\pydevd_cython_win32_39_64.pyx", line 920, in _pydevd_bundle.pydevd_cython_win32_39_64.PyDBFrame.trace_dispatch
  File "_pydevd_bundle\pydevd_cython_win32_39_64.pyx", line 317, in _pydevd_bundle.pydevd_cython_win32_39_64.PyDBFrame.do_wait_suspend
  File "C:\Program Files\JetBrains\PyCharm Community Edition 2021.2.3\plugins\python-ce\helpers\pydev\pydevd.py", line 1147, in do_wait_suspend
    self._do_wait_suspend(thread, frame, event, arg, suspend_type, from_this_thread)
  File "C:\Program Files\JetBrains\PyCharm Community Edition 2021.2.3\plugins\python-ce\helpers\pydev\pydevd.py", line 1162, in _do_wait_suspend
    time.sleep(0.01)
KeyboardInterrupt
ERROR:asyncio:Task exception was never retrieved
future: <Task finished name='Task-11' coro=<UpdateMethods._dispatch_update() done, defined at C:\Users\caleb\OneDrive\Desktop\Dev Projects\Python Projects\trade_bot - Copy\venv\lib\site-packages\telethon\client\updates.py:399> exception=KeyboardInterrupt()>
Traceback (most recent call last):
  File "C:\Users\caleb\OneDrive\Desktop\Dev Projects\Python Projects\trade_bot - Copy\venv\lib\site-packages\telethon\client\updates.py", line 84, in run_until_disconnected
    return self.loop.run_until_complete(self._run_until_disconnected())
  File "C:\Users\caleb\AppData\Local\Programs\Python\Python39\lib\asyncio\base_events.py", line 629, in run_until_complete
    self.run_forever()
  File "C:\Users\caleb\AppData\Local\Programs\Python\Python39\lib\asyncio\windows_events.py", line 316, in run_forever
    super().run_forever()
  File "C:\Users\caleb\AppData\Local\Programs\Python\Python39\lib\asyncio\base_events.py", line 596, in run_forever
    self._run_once()
  File "C:\Users\caleb\AppData\Local\Programs\Python\Python39\lib\asyncio\base_events.py", line 1890, in _run_once
    handle._run()
  File "C:\Users\caleb\AppData\Local\Programs\Python\Python39\lib\asyncio\events.py", line 80, in _run
    self._context.run(self._callback, *self._args)
  File "C:\Users\caleb\OneDrive\Desktop\Dev Projects\Python Projects\trade_bot - Copy\venv\lib\site-packages\telethon\client\updates.py", line 467, in _dispatch_update
    await callback(event)
  File "C:\Users\caleb\OneDrive\Desktop\Dev Projects\Python Projects\trade_bot - Copy\run_bot.py", line 31, in handler
    message_json = message_parser.get_trade_info(input_text, edited_message=isinstance(event,
  File "C:\Users\caleb\OneDrive\Desktop\Dev Projects\Python Projects\trade_bot - Copy\message_parser\text_parser.py", line 32, in get_trade_info
    return self.parse_message()
  File "C:\Users\caleb\OneDrive\Desktop\Dev Projects\Python Projects\trade_bot - Copy\message_parser\text_parser.py", line 45, in parse_message
    self.parse_open_trade_message()
  File "C:\Users\caleb\OneDrive\Desktop\Dev Projects\Python Projects\trade_bot - Copy\message_parser\text_parser.py", line 62, in parse_open_trade_message
    self.parse_index_name()
  File "C:\Users\caleb\OneDrive\Desktop\Dev Projects\Python Projects\trade_bot - Copy\message_parser\text_parser.py", line 154, in parse_index_name
    self.RESULT.update(self.get_index_from_string(index_string))
  File "C:\Users\caleb\OneDrive\Desktop\Dev Projects\Python Projects\trade_bot - Copy\message_parser\text_parser.py", line 195, in get_index_from_string
    if any(option in string for option in self.INDEX_MAPPER[key]["OPTIONS"]) or string == key:
  File "_pydevd_bundle\pydevd_cython_win32_39_64.pyx", line 1179, in _pydevd_bundle.pydevd_cython_win32_39_64.SafeCallWrapper.__call__
  File "_pydevd_bundle\pydevd_cython_win32_39_64.pyx", line 620, in _pydevd_bundle.pydevd_cython_win32_39_64.PyDBFrame.trace_dispatch
  File "_pydevd_bundle\pydevd_cython_win32_39_64.pyx", line 1095, in _pydevd_bundle.pydevd_cython_win32_39_64.PyDBFrame.trace_dispatch
  File "_pydevd_bundle\pydevd_cython_win32_39_64.pyx", line 1088, in _pydevd_bundle.pydevd_cython_win32_39_64.PyDBFrame.trace_dispatch
  File "_pydevd_bundle\pydevd_cython_win32_39_64.pyx", line 317, in _pydevd_bundle.pydevd_cython_win32_39_64.PyDBFrame.do_wait_suspend
  File "C:\Program Files\JetBrains\PyCharm Community Edition 2021.2.3\plugins\python-ce\helpers\pydev\pydevd.py", line 1147, in do_wait_suspend
    self._do_wait_suspend(thread, frame, event, arg, suspend_type, from_this_thread)
  File "C:\Program Files\JetBrains\PyCharm Community Edition 2021.2.3\plugins\python-ce\helpers\pydev\pydevd.py", line 1162, in _do_wait_suspend
    time.sleep(0.01)
KeyboardInterrupt
ERROR:asyncio:Task exception was never retrieved
future: <Task finished name='Task-11' coro=<UpdateMethods._dispatch_update() done, defined at C:\Users\caleb\OneDrive\Desktop\Dev Projects\Python Projects\trade_bot - Copy\venv\lib\site-packages\telethon\client\updates.py:399> exception=KeyboardInterrupt()>
Traceback (most recent call last):
  File "C:\Users\caleb\OneDrive\Desktop\Dev Projects\Python Projects\trade_bot - Copy\venv\lib\site-packages\telethon\client\updates.py", line 84, in run_until_disconnected
    return self.loop.run_until_complete(self._run_until_disconnected())
  File "C:\Users\caleb\AppData\Local\Programs\Python\Python39\lib\asyncio\base_events.py", line 629, in run_until_complete
    self.run_forever()
  File "C:\Users\caleb\AppData\Local\Programs\Python\Python39\lib\asyncio\windows_events.py", line 316, in run_forever
    super().run_forever()
  File "C:\Users\caleb\AppData\Local\Programs\Python\Python39\lib\asyncio\base_events.py", line 596, in run_forever
    self._run_once()
  File "C:\Users\caleb\AppData\Local\Programs\Python\Python39\lib\asyncio\base_events.py", line 1890, in _run_once
    handle._run()
  File "C:\Users\caleb\AppData\Local\Programs\Python\Python39\lib\asyncio\events.py", line 80, in _run
    self._context.run(self._callback, *self._args)
  File "C:\Users\caleb\OneDrive\Desktop\Dev Projects\Python Projects\trade_bot - Copy\venv\lib\site-packages\telethon\client\updates.py", line 467, in _dispatch_update
    await callback(event)
  File "C:\Users\caleb\OneDrive\Desktop\Dev Projects\Python Projects\trade_bot - Copy\run_bot.py", line 31, in handler
    message_json = message_parser.get_trade_info(input_text, edited_message=isinstance(event,
  File "C:\Users\caleb\OneDrive\Desktop\Dev Projects\Python Projects\trade_bot - Copy\message_parser\text_parser.py", line 32, in get_trade_info
    return self.parse_message()
  File "C:\Users\caleb\OneDrive\Desktop\Dev Projects\Python Projects\trade_bot - Copy\message_parser\text_parser.py", line 45, in parse_message
    self.parse_open_trade_message()
  File "C:\Users\caleb\OneDrive\Desktop\Dev Projects\Python Projects\trade_bot - Copy\message_parser\text_parser.py", line 62, in parse_open_trade_message
    self.parse_index_name()
  File "C:\Users\caleb\OneDrive\Desktop\Dev Projects\Python Projects\trade_bot - Copy\message_parser\text_parser.py", line 154, in parse_index_name
    self.RESULT.update(self.get_index_from_string(index_string))
  File "C:\Users\caleb\OneDrive\Desktop\Dev Projects\Python Projects\trade_bot - Copy\message_parser\text_parser.py", line 195, in get_index_from_string
    if any(option in string for option in self.INDEX_MAPPER[key]["OPTIONS"]) or string == key:
  File "C:\Users\caleb\OneDrive\Desktop\Dev Projects\Python Projects\trade_bot - Copy\message_parser\text_parser.py", line 195, in get_index_from_string
    if any(option in string for option in self.INDEX_MAPPER[key]["OPTIONS"]) or string == key:
  File "_pydevd_bundle\pydevd_cython_win32_39_64.pyx", line 1179, in _pydevd_bundle.pydevd_cython_win32_39_64.SafeCallWrapper.__call__
  File "_pydevd_bundle\pydevd_cython_win32_39_64.pyx", line 620, in _pydevd_bundle.pydevd_cython_win32_39_64.PyDBFrame.trace_dispatch
  File "_pydevd_bundle\pydevd_cython_win32_39_64.pyx", line 1095, in _pydevd_bundle.pydevd_cython_win32_39_64.PyDBFrame.trace_dispatch
  File "_pydevd_bundle\pydevd_cython_win32_39_64.pyx", line 1057, in _pydevd_bundle.pydevd_cython_win32_39_64.PyDBFrame.trace_dispatch
  File "_pydevd_bundle\pydevd_cython_win32_39_64.pyx", line 317, in _pydevd_bundle.pydevd_cython_win32_39_64.PyDBFrame.do_wait_suspend
  File "C:\Program Files\JetBrains\PyCharm Community Edition 2021.2.3\plugins\python-ce\helpers\pydev\pydevd.py", line 1147, in do_wait_suspend
    self._do_wait_suspend(thread, frame, event, arg, suspend_type, from_this_thread)
  File "C:\Program Files\JetBrains\PyCharm Community Edition 2021.2.3\plugins\python-ce\helpers\pydev\pydevd.py", line 1162, in _do_wait_suspend
    time.sleep(0.01)
KeyboardInterrupt
ERROR:telethon.client.updates:Unhandled exception on handler
Traceback (most recent call last):
  File "C:\Users\caleb\OneDrive\Desktop\Dev Projects\Python Projects\trade_bot - Copy\venv\lib\site-packages\telethon\client\updates.py", line 467, in _dispatch_update
    await callback(event)
  File "C:\Users\caleb\OneDrive\Desktop\Dev Projects\Python Projects\trade_bot - Copy\run_bot.py", line 35, in handler
    blotter_message_json = blotter.trade_position(message_json)
  File "C:\Users\caleb\OneDrive\Desktop\Dev Projects\Python Projects\trade_bot - Copy\blotter\daily_blotter.py", line 50, in trade_position
    self.open_trade()
  File "C:\Users\caleb\OneDrive\Desktop\Dev Projects\Python Projects\trade_bot - Copy\blotter\daily_blotter.py", line 96, in open_trade
    self.BLOTTER[self.message_json['index']][datetime.now().strftime('%Y-%m-%d %H:%M:%S.%f')] = self.message_json
KeyError: 'BITCOIN'
ERROR:asyncio:Task exception was never retrieved
future: <Task finished name='Task-12' coro=<UpdateMethods._dispatch_update() done, defined at C:\Users\caleb\OneDrive\Desktop\Dev Projects\Python Projects\trade_bot - Copy\venv\lib\site-packages\telethon\client\updates.py:399> exception=KeyboardInterrupt()>
Traceback (most recent call last):
  File "C:\Users\caleb\OneDrive\Desktop\Dev Projects\Python Projects\trade_bot - Copy\venv\lib\site-packages\telethon\client\updates.py", line 84, in run_until_disconnected
    return self.loop.run_until_complete(self._run_until_disconnected())
  File "C:\Users\caleb\AppData\Local\Programs\Python\Python39\lib\asyncio\base_events.py", line 629, in run_until_complete
    self.run_forever()
  File "C:\Users\caleb\AppData\Local\Programs\Python\Python39\lib\asyncio\windows_events.py", line 316, in run_forever
    super().run_forever()
  File "C:\Users\caleb\AppData\Local\Programs\Python\Python39\lib\asyncio\base_events.py", line 596, in run_forever
    self._run_once()
  File "C:\Users\caleb\AppData\Local\Programs\Python\Python39\lib\asyncio\base_events.py", line 1890, in _run_once
    handle._run()
  File "C:\Users\caleb\AppData\Local\Programs\Python\Python39\lib\asyncio\events.py", line 80, in _run
    self._context.run(self._callback, *self._args)
  File "C:\Users\caleb\OneDrive\Desktop\Dev Projects\Python Projects\trade_bot - Copy\venv\lib\site-packages\telethon\client\updates.py", line 467, in _dispatch_update
    await callback(event)
  File "C:\Users\caleb\OneDrive\Desktop\Dev Projects\Python Projects\trade_bot - Copy\run_bot.py", line 35, in handler
    events.messageedited.MessageEdited.Event))
  File "C:\Users\caleb\OneDrive\Desktop\Dev Projects\Python Projects\trade_bot - Copy\blotter\daily_blotter.py", line 50, in trade_position
    self.open_trade()
  File "C:\Users\caleb\OneDrive\Desktop\Dev Projects\Python Projects\trade_bot - Copy\blotter\daily_blotter.py", line 93, in open_trade
    self.message_json.update(deal_reference)
  File "C:\Users\caleb\OneDrive\Desktop\Dev Projects\Python Projects\trade_bot - Copy\blotter\daily_blotter.py", line 93, in open_trade
    self.message_json.update(deal_reference)
  File "_pydevd_bundle\pydevd_cython_win32_39_64.pyx", line 1179, in _pydevd_bundle.pydevd_cython_win32_39_64.SafeCallWrapper.__call__
  File "_pydevd_bundle\pydevd_cython_win32_39_64.pyx", line 620, in _pydevd_bundle.pydevd_cython_win32_39_64.PyDBFrame.trace_dispatch
  File "_pydevd_bundle\pydevd_cython_win32_39_64.pyx", line 1095, in _pydevd_bundle.pydevd_cython_win32_39_64.PyDBFrame.trace_dispatch
  File "_pydevd_bundle\pydevd_cython_win32_39_64.pyx", line 1057, in _pydevd_bundle.pydevd_cython_win32_39_64.PyDBFrame.trace_dispatch
  File "_pydevd_bundle\pydevd_cython_win32_39_64.pyx", line 317, in _pydevd_bundle.pydevd_cython_win32_39_64.PyDBFrame.do_wait_suspend
  File "C:\Program Files\JetBrains\PyCharm Community Edition 2021.2.3\plugins\python-ce\helpers\pydev\pydevd.py", line 1147, in do_wait_suspend
    self._do_wait_suspend(thread, frame, event, arg, suspend_type, from_this_thread)
  File "C:\Program Files\JetBrains\PyCharm Community Edition 2021.2.3\plugins\python-ce\helpers\pydev\pydevd.py", line 1162, in _do_wait_suspend
    time.sleep(0.01)
KeyboardInterrupt
ERROR:telethon.client.updates:Unhandled exception on handler
Traceback (most recent call last):
  File "C:\Users\caleb\OneDrive\Desktop\Dev Projects\Python Projects\trade_bot - Copy\venv\lib\site-packages\telethon\client\updates.py", line 467, in _dispatch_update
    await callback(event)
  File "C:\Users\caleb\OneDrive\Desktop\Dev Projects\Python Projects\trade_bot - Copy\run_bot.py", line 38, in handler
    blotter_message_json = blotter.trade_position(message_json)
  File "C:\Users\caleb\OneDrive\Desktop\Dev Projects\Python Projects\trade_bot - Copy\blotter\daily_blotter.py", line 50, in trade_position
    self.open_trade()
  File "C:\Users\caleb\OneDrive\Desktop\Dev Projects\Python Projects\trade_bot - Copy\blotter\daily_blotter.py", line 96, in open_trade
    self.BLOTTER[self.message_json['index']][datetime.now().strftime('%Y-%m-%d %H:%M:%S.%f')] = self.message_json
KeyError: 'BITCOIN'
ERROR:telethon.client.updates:Unhandled exception on handler
Traceback (most recent call last):
  File "C:\Users\caleb\OneDrive\Desktop\Dev Projects\Python Projects\trade_bot - Copy\venv\lib\site-packages\telethon\client\updates.py", line 467, in _dispatch_update
    await callback(event)
  File "C:\Users\caleb\OneDrive\Desktop\Dev Projects\Python Projects\trade_bot - Copy\run_bot.py", line 38, in handler
    blotter_message_json = blotter.trade_position(message_json)
  File "C:\Users\caleb\OneDrive\Desktop\Dev Projects\Python Projects\trade_bot - Copy\blotter\daily_blotter.py", line 50, in trade_position
    self.open_trade()
  File "C:\Users\caleb\OneDrive\Desktop\Dev Projects\Python Projects\trade_bot - Copy\blotter\daily_blotter.py", line 96, in open_trade
    self.BLOTTER[self.message_json['index']][datetime.now().strftime('%Y-%m-%d %H:%M:%S.%f')] = self.message_json
KeyError: 'BITCOIN'
ERROR:telethon.client.updates:Unhandled exception on handler
Traceback (most recent call last):
  File "C:\Users\caleb\OneDrive\Desktop\Dev Projects\Python Projects\trade_bot - Copy\venv\lib\site-packages\telethon\client\updates.py", line 467, in _dispatch_update
    await callback(event)
  File "C:\Users\caleb\OneDrive\Desktop\Dev Projects\Python Projects\trade_bot - Copy\run_bot.py", line 38, in handler
    blotter_message_json = blotter.trade_position(message_json)
  File "C:\Users\caleb\OneDrive\Desktop\Dev Projects\Python Projects\trade_bot - Copy\blotter\daily_blotter.py", line 50, in trade_position
    self.open_trade()
  File "C:\Users\caleb\OneDrive\Desktop\Dev Projects\Python Projects\trade_bot - Copy\blotter\daily_blotter.py", line 96, in open_trade
    self.BLOTTER[self.message_json['index']][datetime.now().strftime('%Y-%m-%d %H:%M:%S.%f')] = self.message_json
KeyError: 'BITCOIN'
ERROR:asyncio:Task exception was never retrieved
future: <Task finished name='Task-16' coro=<UpdateMethods._dispatch_update() done, defined at C:\Users\caleb\OneDrive\Desktop\Dev Projects\Python Projects\trade_bot - Copy\venv\lib\site-packages\telethon\client\updates.py:399> exception=KeyboardInterrupt()>
Traceback (most recent call last):
  File "C:\Users\caleb\OneDrive\Desktop\Dev Projects\Python Projects\trade_bot - Copy\venv\lib\site-packages\telethon\client\updates.py", line 84, in run_until_disconnected
    return self.loop.run_until_complete(self._run_until_disconnected())
  File "C:\Users\caleb\AppData\Local\Programs\Python\Python39\lib\asyncio\base_events.py", line 629, in run_until_complete
    self.run_forever()
  File "C:\Users\caleb\AppData\Local\Programs\Python\Python39\lib\asyncio\windows_events.py", line 316, in run_forever
    super().run_forever()
  File "C:\Users\caleb\AppData\Local\Programs\Python\Python39\lib\asyncio\base_events.py", line 596, in run_forever
    self._run_once()
  File "C:\Users\caleb\AppData\Local\Programs\Python\Python39\lib\asyncio\base_events.py", line 1890, in _run_once
    handle._run()
  File "C:\Users\caleb\AppData\Local\Programs\Python\Python39\lib\asyncio\events.py", line 80, in _run
    self._context.run(self._callback, *self._args)
  File "C:\Users\caleb\OneDrive\Desktop\Dev Projects\Python Projects\trade_bot - Copy\venv\lib\site-packages\telethon\client\updates.py", line 467, in _dispatch_update
    await callback(event)
  File "C:\Users\caleb\OneDrive\Desktop\Dev Projects\Python Projects\trade_bot - Copy\run_bot.py", line 38, in handler
    blotter_message_json = blotter.trade_position(message_json)
  File "C:\Users\caleb\OneDrive\Desktop\Dev Projects\Python Projects\trade_bot - Copy\blotter\daily_blotter.py", line 50, in trade_position
    self.open_trade()
  File "C:\Users\caleb\OneDrive\Desktop\Dev Projects\Python Projects\trade_bot - Copy\blotter\daily_blotter.py", line 96, in open_trade
    self.BLOTTER[self.message_json['index']][datetime.now().strftime('%Y-%m-%d %H:%M:%S.%f')] = self.message_json
  File "C:\Users\caleb\OneDrive\Desktop\Dev Projects\Python Projects\trade_bot - Copy\blotter\daily_blotter.py", line 96, in open_trade
    self.BLOTTER[self.message_json['index']][datetime.now().strftime('%Y-%m-%d %H:%M:%S.%f')] = self.message_json
  File "_pydevd_bundle\pydevd_cython_win32_39_64.pyx", line 1179, in _pydevd_bundle.pydevd_cython_win32_39_64.SafeCallWrapper.__call__
  File "_pydevd_bundle\pydevd_cython_win32_39_64.pyx", line 620, in _pydevd_bundle.pydevd_cython_win32_39_64.PyDBFrame.trace_dispatch
  File "_pydevd_bundle\pydevd_cython_win32_39_64.pyx", line 1095, in _pydevd_bundle.pydevd_cython_win32_39_64.PyDBFrame.trace_dispatch
  File "_pydevd_bundle\pydevd_cython_win32_39_64.pyx", line 1057, in _pydevd_bundle.pydevd_cython_win32_39_64.PyDBFrame.trace_dispatch
  File "_pydevd_bundle\pydevd_cython_win32_39_64.pyx", line 317, in _pydevd_bundle.pydevd_cython_win32_39_64.PyDBFrame.do_wait_suspend
  File "C:\Program Files\JetBrains\PyCharm Community Edition 2021.2.3\plugins\python-ce\helpers\pydev\pydevd.py", line 1147, in do_wait_suspend
    self._do_wait_suspend(thread, frame, event, arg, suspend_type, from_this_thread)
  File "C:\Program Files\JetBrains\PyCharm Community Edition 2021.2.3\plugins\python-ce\helpers\pydev\pydevd.py", line 1162, in _do_wait_suspend
    time.sleep(0.01)
KeyboardInterrupt
ERROR:asyncio:Task exception was never retrieved
future: <Task finished name='Task-12' coro=<UpdateMethods._dispatch_update() done, defined at C:\Users\caleb\OneDrive\Desktop\Dev Projects\Python Projects\trade_bot - Copy\venv\lib\site-packages\telethon\client\updates.py:399> exception=KeyboardInterrupt()>
Traceback (most recent call last):
  File "C:\Users\caleb\OneDrive\Desktop\Dev Projects\Python Projects\trade_bot - Copy\venv\lib\site-packages\telethon\client\updates.py", line 84, in run_until_disconnected
    return self.loop.run_until_complete(self._run_until_disconnected())
  File "C:\Users\caleb\AppData\Local\Programs\Python\Python39\lib\asyncio\base_events.py", line 629, in run_until_complete
    self.run_forever()
  File "C:\Users\caleb\AppData\Local\Programs\Python\Python39\lib\asyncio\windows_events.py", line 316, in run_forever
    super().run_forever()
  File "C:\Users\caleb\AppData\Local\Programs\Python\Python39\lib\asyncio\base_events.py", line 596, in run_forever
    self._run_once()
  File "C:\Users\caleb\AppData\Local\Programs\Python\Python39\lib\asyncio\base_events.py", line 1890, in _run_once
    handle._run()
  File "C:\Users\caleb\AppData\Local\Programs\Python\Python39\lib\asyncio\events.py", line 80, in _run
    self._context.run(self._callback, *self._args)
  File "C:\Users\caleb\OneDrive\Desktop\Dev Projects\Python Projects\trade_bot - Copy\venv\lib\site-packages\telethon\client\updates.py", line 467, in _dispatch_update
    await callback(event)
  File "C:\Users\caleb\OneDrive\Desktop\Dev Projects\Python Projects\trade_bot - Copy\run_bot.py", line 38, in handler
    blotter_message_json = blotter.trade_position(message_json)
  File "C:\Users\caleb\OneDrive\Desktop\Dev Projects\Python Projects\trade_bot - Copy\blotter\daily_blotter.py", line 72, in trade_position
    self.get_current_pnl_drilldown()
  File "C:\Users\caleb\OneDrive\Desktop\Dev Projects\Python Projects\trade_bot - Copy\blotter\daily_blotter.py", line 161, in get_current_pnl_drilldown
    self.message_json = self.connector.get_pnl_drilldown(datetime.now())
  File "C:\Users\caleb\OneDrive\Desktop\Dev Projects\Python Projects\trade_bot - Copy\connectors\meta_trader_5.py", line 313, in get_pnl_drilldown
    position_datetime = datetime.datetime.fromtimestamp(position.time)
  File "C:\Users\caleb\OneDrive\Desktop\Dev Projects\Python Projects\trade_bot - Copy\connectors\meta_trader_5.py", line 313, in get_pnl_drilldown
    position_datetime = datetime.datetime.fromtimestamp(position.time)
  File "_pydevd_bundle\pydevd_cython_win32_39_64.pyx", line 1589, in _pydevd_bundle.pydevd_cython_win32_39_64.ThreadTracer.__call__
  File "_pydevd_bundle\pydevd_cython_win32_39_64.pyx", line 929, in _pydevd_bundle.pydevd_cython_win32_39_64.PyDBFrame.trace_dispatch
  File "_pydevd_bundle\pydevd_cython_win32_39_64.pyx", line 920, in _pydevd_bundle.pydevd_cython_win32_39_64.PyDBFrame.trace_dispatch
  File "_pydevd_bundle\pydevd_cython_win32_39_64.pyx", line 317, in _pydevd_bundle.pydevd_cython_win32_39_64.PyDBFrame.do_wait_suspend
  File "C:\Program Files\JetBrains\PyCharm Community Edition 2021.2.3\plugins\python-ce\helpers\pydev\pydevd.py", line 1147, in do_wait_suspend
    self._do_wait_suspend(thread, frame, event, arg, suspend_type, from_this_thread)
  File "C:\Program Files\JetBrains\PyCharm Community Edition 2021.2.3\plugins\python-ce\helpers\pydev\pydevd.py", line 1162, in _do_wait_suspend
    time.sleep(0.01)
KeyboardInterrupt
ERROR:telethon.client.updates:Unhandled exception on handler
Traceback (most recent call last):
  File "C:\Users\caleb\OneDrive\Desktop\Dev Projects\Python Projects\trade_bot - Copy\venv\lib\site-packages\telethon\client\updates.py", line 467, in _dispatch_update
    await callback(event)
  File "C:\Users\caleb\OneDrive\Desktop\Dev Projects\Python Projects\trade_bot - Copy\run_bot.py", line 38, in handler
    blotter_message_json = blotter.trade_position(message_json)
  File "C:\Users\caleb\OneDrive\Desktop\Dev Projects\Python Projects\trade_bot - Copy\blotter\daily_blotter.py", line 72, in trade_position
    self.get_current_pnl_drilldown()
  File "C:\Users\caleb\OneDrive\Desktop\Dev Projects\Python Projects\trade_bot - Copy\blotter\daily_blotter.py", line 161, in get_current_pnl_drilldown
    self.message_json = self.connector.get_pnl_drilldown(datetime.now())
  File "C:\Users\caleb\OneDrive\Desktop\Dev Projects\Python Projects\trade_bot - Copy\connectors\meta_trader_5.py", line 312, in get_pnl_drilldown
    for position in positions:
TypeError: 'NoneType' object is not iterable
ERROR:telethon.client.updates:Unhandled exception on handler
Traceback (most recent call last):
  File "C:\Users\caleb\OneDrive\Desktop\Dev Projects\Python Projects\trade_bot - Copy\venv\lib\site-packages\telethon\client\updates.py", line 467, in _dispatch_update
    await callback(event)
  File "C:\Users\caleb\OneDrive\Desktop\Dev Projects\Python Projects\trade_bot - Copy\run_bot.py", line 38, in handler
    blotter_message_json = blotter.trade_position(message_json)
  File "C:\Users\caleb\OneDrive\Desktop\Dev Projects\Python Projects\trade_bot - Copy\blotter\daily_blotter.py", line 72, in trade_position
    self.get_current_pnl_drilldown()
  File "C:\Users\caleb\OneDrive\Desktop\Dev Projects\Python Projects\trade_bot - Copy\blotter\daily_blotter.py", line 161, in get_current_pnl_drilldown
    self.message_json = self.connector.get_pnl_drilldown(datetime.now())
  File "C:\Users\caleb\OneDrive\Desktop\Dev Projects\Python Projects\trade_bot - Copy\connectors\meta_trader_5.py", line 312, in get_pnl_drilldown
    for position in positions:
TypeError: 'NoneType' object is not iterable
ERROR:asyncio:Task exception was never retrieved
future: <Task finished name='Task-19' coro=<UpdateMethods._dispatch_update() done, defined at C:\Users\caleb\OneDrive\Desktop\Dev Projects\Python Projects\trade_bot - Copy\venv\lib\site-packages\telethon\client\updates.py:399> exception=KeyboardInterrupt()>
Traceback (most recent call last):
  File "C:\Users\caleb\OneDrive\Desktop\Dev Projects\Python Projects\trade_bot - Copy\venv\lib\site-packages\telethon\client\updates.py", line 84, in run_until_disconnected
    return self.loop.run_until_complete(self._run_until_disconnected())
  File "C:\Users\caleb\AppData\Local\Programs\Python\Python39\lib\asyncio\base_events.py", line 629, in run_until_complete
    self.run_forever()
  File "C:\Users\caleb\AppData\Local\Programs\Python\Python39\lib\asyncio\windows_events.py", line 316, in run_forever
    super().run_forever()
  File "C:\Users\caleb\AppData\Local\Programs\Python\Python39\lib\asyncio\base_events.py", line 596, in run_forever
    self._run_once()
  File "C:\Users\caleb\AppData\Local\Programs\Python\Python39\lib\asyncio\base_events.py", line 1890, in _run_once
    handle._run()
  File "C:\Users\caleb\AppData\Local\Programs\Python\Python39\lib\asyncio\events.py", line 80, in _run
    self._context.run(self._callback, *self._args)
  File "C:\Users\caleb\OneDrive\Desktop\Dev Projects\Python Projects\trade_bot - Copy\venv\lib\site-packages\telethon\client\updates.py", line 467, in _dispatch_update
    await callback(event)
  File "C:\Users\caleb\OneDrive\Desktop\Dev Projects\Python Projects\trade_bot - Copy\run_bot.py", line 37, in handler
    blotter_message_json = blotter.trade_position(message_json)
  File "C:\Users\caleb\OneDrive\Desktop\Dev Projects\Python Projects\trade_bot - Copy\blotter\daily_blotter.py", line 66, in trade_position
    self.modify_stop_loss()
  File "C:\Users\caleb\OneDrive\Desktop\Dev Projects\Python Projects\trade_bot - Copy\blotter\daily_blotter.py", line 149, in modify_stop_loss
    confirmation_message = self.connector.modify_stop_loss_for_symbol(symbol = symbol,new_stop_level= self.message_json["stop_loss_level"])
  File "C:\Users\caleb\OneDrive\Desktop\Dev Projects\Python Projects\trade_bot - Copy\connectors\meta_trader_5.py", line 278, in modify_stop_loss_for_symbol
    results[str(position['ticket'])] = self.modify_stop_loss_for_ticket(ticket = position['ticket'], new_stop_level = new_stop_level)
  File "C:\Users\caleb\OneDrive\Desktop\Dev Projects\Python Projects\trade_bot - Copy\connectors\meta_trader_5.py", line 246, in modify_stop_loss_for_ticket
    final_stop_level = max(position["price_open"]-100, new_stop_level) if position['type'] == 0 else min(position["price_open"]+100, new_stop_level)
  File "C:\Users\caleb\OneDrive\Desktop\Dev Projects\Python Projects\trade_bot - Copy\connectors\meta_trader_5.py", line 246, in modify_stop_loss_for_ticket
    final_stop_level = max(position["price_open"]-100, new_stop_level) if position['type'] == 0 else min(position["price_open"]+100, new_stop_level)
  File "_pydevd_bundle\pydevd_cython_win32_39_64.pyx", line 1589, in _pydevd_bundle.pydevd_cython_win32_39_64.ThreadTracer.__call__
  File "_pydevd_bundle\pydevd_cython_win32_39_64.pyx", line 929, in _pydevd_bundle.pydevd_cython_win32_39_64.PyDBFrame.trace_dispatch
  File "_pydevd_bundle\pydevd_cython_win32_39_64.pyx", line 920, in _pydevd_bundle.pydevd_cython_win32_39_64.PyDBFrame.trace_dispatch
  File "_pydevd_bundle\pydevd_cython_win32_39_64.pyx", line 317, in _pydevd_bundle.pydevd_cython_win32_39_64.PyDBFrame.do_wait_suspend
  File "C:\Program Files\JetBrains\PyCharm Community Edition 2021.2.3\plugins\python-ce\helpers\pydev\pydevd.py", line 1147, in do_wait_suspend
    self._do_wait_suspend(thread, frame, event, arg, suspend_type, from_this_thread)
  File "C:\Program Files\JetBrains\PyCharm Community Edition 2021.2.3\plugins\python-ce\helpers\pydev\pydevd.py", line 1162, in _do_wait_suspend
    time.sleep(0.01)
KeyboardInterrupt
ERROR:asyncio:Task exception was never retrieved
future: <Task finished name='Task-21' coro=<UpdateMethods._dispatch_update() done, defined at C:\Users\caleb\OneDrive\Desktop\Dev Projects\Python Projects\trade_bot - Copy\venv\lib\site-packages\telethon\client\updates.py:399> exception=KeyboardInterrupt()>
Traceback (most recent call last):
  File "C:\Users\caleb\OneDrive\Desktop\Dev Projects\Python Projects\trade_bot - Copy\venv\lib\site-packages\telethon\client\updates.py", line 84, in run_until_disconnected
    return self.loop.run_until_complete(self._run_until_disconnected())
  File "C:\Users\caleb\AppData\Local\Programs\Python\Python39\lib\asyncio\base_events.py", line 629, in run_until_complete
    self.run_forever()
  File "C:\Users\caleb\AppData\Local\Programs\Python\Python39\lib\asyncio\windows_events.py", line 316, in run_forever
    super().run_forever()
  File "C:\Users\caleb\AppData\Local\Programs\Python\Python39\lib\asyncio\base_events.py", line 596, in run_forever
    self._run_once()
  File "C:\Users\caleb\AppData\Local\Programs\Python\Python39\lib\asyncio\base_events.py", line 1890, in _run_once
    handle._run()
  File "C:\Users\caleb\AppData\Local\Programs\Python\Python39\lib\asyncio\events.py", line 80, in _run
    self._context.run(self._callback, *self._args)
  File "C:\Users\caleb\OneDrive\Desktop\Dev Projects\Python Projects\trade_bot - Copy\venv\lib\site-packages\telethon\client\updates.py", line 467, in _dispatch_update
    await callback(event)
  File "C:\Users\caleb\OneDrive\Desktop\Dev Projects\Python Projects\trade_bot - Copy\run_bot.py", line 37, in handler
    blotter_message_json = blotter.trade_position(message_json)
  File "C:\Users\caleb\OneDrive\Desktop\Dev Projects\Python Projects\trade_bot - Copy\blotter\daily_blotter.py", line 66, in trade_position
    self.modify_stop_loss()
  File "C:\Users\caleb\OneDrive\Desktop\Dev Projects\Python Projects\trade_bot - Copy\blotter\daily_blotter.py", line 146, in modify_stop_loss
    if self.message_json['stop_loss_level'] == "BREAKEVEN":
  File "C:\Users\caleb\OneDrive\Desktop\Dev Projects\Python Projects\trade_bot - Copy\blotter\daily_blotter.py", line 146, in modify_stop_loss
    if self.message_json['stop_loss_level'] == "BREAKEVEN":
  File "_pydevd_bundle\pydevd_cython_win32_39_64.pyx", line 1589, in _pydevd_bundle.pydevd_cython_win32_39_64.ThreadTracer.__call__
  File "_pydevd_bundle\pydevd_cython_win32_39_64.pyx", line 929, in _pydevd_bundle.pydevd_cython_win32_39_64.PyDBFrame.trace_dispatch
  File "_pydevd_bundle\pydevd_cython_win32_39_64.pyx", line 920, in _pydevd_bundle.pydevd_cython_win32_39_64.PyDBFrame.trace_dispatch
  File "_pydevd_bundle\pydevd_cython_win32_39_64.pyx", line 317, in _pydevd_bundle.pydevd_cython_win32_39_64.PyDBFrame.do_wait_suspend
  File "C:\Program Files\JetBrains\PyCharm Community Edition 2021.2.3\plugins\python-ce\helpers\pydev\pydevd.py", line 1147, in do_wait_suspend
    self._do_wait_suspend(thread, frame, event, arg, suspend_type, from_this_thread)
  File "C:\Program Files\JetBrains\PyCharm Community Edition 2021.2.3\plugins\python-ce\helpers\pydev\pydevd.py", line 1162, in _do_wait_suspend
    time.sleep(0.01)
KeyboardInterrupt
ERROR:telethon.client.updates:Unhandled exception on handler
Traceback (most recent call last):
  File "C:\Users\caleb\OneDrive\Desktop\Dev Projects\Python Projects\trade_bot - Copy\venv\lib\site-packages\telethon\client\updates.py", line 467, in _dispatch_update
    await callback(event)
  File "C:\Users\caleb\OneDrive\Desktop\Dev Projects\Python Projects\trade_bot - Copy\run_bot.py", line 37, in handler
    blotter_message_json = blotter.trade_position(message_json)
  File "C:\Users\caleb\OneDrive\Desktop\Dev Projects\Python Projects\trade_bot - Copy\blotter\daily_blotter.py", line 69, in trade_position
    self.modify_stop_loss_for_most_recent_trade()
  File "C:\Users\caleb\OneDrive\Desktop\Dev Projects\Python Projects\trade_bot - Copy\blotter\daily_blotter.py", line 155, in modify_stop_loss_for_most_recent_trade
    self.connector.modify_stop_loss_for_most_recent_position(symbol, self.message_json['stop_loss'])
  File "C:\Users\caleb\OneDrive\Desktop\Dev Projects\Python Projects\trade_bot - Copy\connectors\meta_trader_5.py", line 294, in modify_stop_loss_for_most_recent_position
    most_recent_date = max(list(positions.keys()))
ValueError: max() arg is an empty sequence
ERROR:telethon.client.updates:Unhandled exception on handler
Traceback (most recent call last):
  File "C:\Users\caleb\OneDrive\Desktop\Dev Projects\Python Projects\trade_bot - Copy\venv\lib\site-packages\telethon\client\updates.py", line 467, in _dispatch_update
    await callback(event)
  File "C:\Users\caleb\OneDrive\Desktop\Dev Projects\Python Projects\trade_bot - Copy\run_bot.py", line 37, in handler
    blotter_message_json = blotter.trade_position(message_json)
  File "C:\Users\caleb\OneDrive\Desktop\Dev Projects\Python Projects\trade_bot - Copy\blotter\daily_blotter.py", line 63, in trade_position
    self.close_n_previous_trades()
  File "C:\Users\caleb\OneDrive\Desktop\Dev Projects\Python Projects\trade_bot - Copy\blotter\daily_blotter.py", line 122, in close_n_previous_trades
    self.BLOTTER[self.message_json['index']].pop(confirmation['time_msc'])
KeyError: 1658226081073
ERROR:telethon.client.updates:Unhandled exception on handler
Traceback (most recent call last):
  File "C:\Users\caleb\OneDrive\Desktop\Dev Projects\Python Projects\trade_bot - Copy\venv\lib\site-packages\telethon\client\updates.py", line 467, in _dispatch_update
    await callback(event)
  File "C:\Users\caleb\OneDrive\Desktop\Dev Projects\Python Projects\trade_bot - Copy\run_bot.py", line 37, in handler
    blotter_message_json = blotter.trade_position(message_json)
  File "C:\Users\caleb\OneDrive\Desktop\Dev Projects\Python Projects\trade_bot - Copy\blotter\daily_blotter.py", line 57, in trade_position
    self.close_oldest_index_position()
  File "C:\Users\caleb\OneDrive\Desktop\Dev Projects\Python Projects\trade_bot - Copy\blotter\daily_blotter.py", line 140, in close_oldest_index_position
    confirmation = self.connector.close_market_order_by_order_of_open(symbol = symbol, first = True)
  File "C:\Users\caleb\OneDrive\Desktop\Dev Projects\Python Projects\trade_bot - Copy\connectors\meta_trader_5.py", line 207, in close_market_order_by_order_of_open
    pertinent_date = dates[order]
IndexError: list index out of range
ERROR:telethon.client.updates:Unhandled exception on handler
Traceback (most recent call last):
  File "C:\Users\caleb\OneDrive\Desktop\Dev Projects\Python Projects\trade_bot - Copy\venv\lib\site-packages\telethon\client\updates.py", line 467, in _dispatch_update
    await callback(event)
  File "C:\Users\caleb\OneDrive\Desktop\Dev Projects\Python Projects\trade_bot - Copy\run_bot.py", line 37, in handler
    blotter_message_json = blotter.trade_position(message_json)
  File "C:\Users\caleb\OneDrive\Desktop\Dev Projects\Python Projects\trade_bot - Copy\blotter\daily_blotter.py", line 57, in trade_position
    self.close_oldest_index_position()
  File "C:\Users\caleb\OneDrive\Desktop\Dev Projects\Python Projects\trade_bot - Copy\blotter\daily_blotter.py", line 140, in close_oldest_index_position
    confirmation = self.connector.close_market_order_by_order_of_open(symbol = symbol, first = True)
  File "C:\Users\caleb\OneDrive\Desktop\Dev Projects\Python Projects\trade_bot - Copy\connectors\meta_trader_5.py", line 207, in close_market_order_by_order_of_open
    pertinent_date = dates[order]
IndexError: list index out of range
ERROR:telethon.client.updates:Unhandled exception on handler
Traceback (most recent call last):
  File "C:\Users\caleb\OneDrive\Desktop\Dev Projects\Python Projects\trade_bot - Copy\venv\lib\site-packages\telethon\client\updates.py", line 467, in _dispatch_update
    await callback(event)
  File "C:\Users\caleb\OneDrive\Desktop\Dev Projects\Python Projects\trade_bot - Copy\run_bot.py", line 37, in handler
    blotter_message_json = blotter.trade_position(message_json)
  File "C:\Users\caleb\OneDrive\Desktop\Dev Projects\Python Projects\trade_bot - Copy\blotter\daily_blotter.py", line 57, in trade_position
    self.close_oldest_index_position()
  File "C:\Users\caleb\OneDrive\Desktop\Dev Projects\Python Projects\trade_bot - Copy\blotter\daily_blotter.py", line 140, in close_oldest_index_position
    confirmation = self.connector.close_market_order_by_order_of_open(symbol = symbol, first = True)
  File "C:\Users\caleb\OneDrive\Desktop\Dev Projects\Python Projects\trade_bot - Copy\connectors\meta_trader_5.py", line 207, in close_market_order_by_order_of_open
    pertinent_date = dates[order]
IndexError: list index out of range
WARNING:telethon.network.mtprotosender:Attempt 1 at connecting failed: OSError: [WinError 1232] The network location cannot be reached. For information about network troubleshooting, see Windows Help
WARNING:telethon.network.mtprotosender:Attempt 2 at connecting failed: OSError: [WinError 1232] The network location cannot be reached. For information about network troubleshooting, see Windows Help
WARNING:telethon.network.mtprotosender:Attempt 3 at connecting failed: OSError: [WinError 1231] The network location cannot be reached. For information about network troubleshooting, see Windows Help
WARNING:telethon.network.mtprotosender:Attempt 4 at connecting failed: OSError: [WinError 1231] The network location cannot be reached. For information about network troubleshooting, see Windows Help
WARNING:telethon.network.mtprotosender:Attempt 5 at connecting failed: OSError: [WinError 1231] The network location cannot be reached. For information about network troubleshooting, see Windows Help
WARNING:telethon.network.mtprotosender:Attempt 6 at connecting failed: OSError: [WinError 1231] The network location cannot be reached. For information about network troubleshooting, see Windows Help
WARNING:telethon.network.mtprotosender:Attempt 1 at connecting failed: OSError: [WinError 1231] The network location cannot be reached. For information about network troubleshooting, see Windows Help
WARNING:telethon.network.mtprotosender:Attempt 2 at connecting failed: OSError: [WinError 1231] The network location cannot be reached. For information about network troubleshooting, see Windows Help
WARNING:telethon.network.mtprotosender:Attempt 3 at connecting failed: OSError: [WinError 1231] The network location cannot be reached. For information about network troubleshooting, see Windows Help
WARNING:telethon.network.mtprotosender:Attempt 4 at connecting failed: OSError: [WinError 1231] The network location cannot be reached. For information about network troubleshooting, see Windows Help
ERROR:telethon.client.updates:Unhandled exception on handler
Traceback (most recent call last):
  File "C:\Users\caleb\OneDrive\Desktop\Dev Projects\Python Projects\trade_bot - Copy\venv\lib\site-packages\telethon\client\updates.py", line 467, in _dispatch_update
    await callback(event)
  File "C:\Users\caleb\OneDrive\Desktop\Dev Projects\Python Projects\trade_bot - Copy\run_bot.py", line 37, in handler
    blotter_message_json = blotter.trade_position(message_json)
  File "C:\Users\caleb\OneDrive\Desktop\Dev Projects\Python Projects\trade_bot - Copy\blotter\daily_blotter.py", line 63, in trade_position
    self.close_n_previous_trades()
  File "C:\Users\caleb\OneDrive\Desktop\Dev Projects\Python Projects\trade_bot - Copy\blotter\daily_blotter.py", line 122, in close_n_previous_trades
    self.BLOTTER[self.message_json['index']].pop(confirmation['time_msc'])
KeyError: 1658514139859
ERROR:telethon.client.updates:Unhandled exception on handler
Traceback (most recent call last):
  File "C:\Users\caleb\OneDrive\Desktop\Dev Projects\Python Projects\trade_bot - Copy\venv\lib\site-packages\telethon\client\updates.py", line 467, in _dispatch_update
    await callback(event)
  File "C:\Users\caleb\OneDrive\Desktop\Dev Projects\Python Projects\trade_bot - Copy\run_bot.py", line 37, in handler
    blotter_message_json = blotter.trade_position(message_json)
  File "C:\Users\caleb\OneDrive\Desktop\Dev Projects\Python Projects\trade_bot - Copy\blotter\daily_blotter.py", line 63, in trade_position
    self.close_n_previous_trades()
  File "C:\Users\caleb\OneDrive\Desktop\Dev Projects\Python Projects\trade_bot - Copy\blotter\daily_blotter.py", line 122, in close_n_previous_trades
    self.BLOTTER[self.message_json['index']].pop(confirmation['time_msc'])
KeyError: 1658514222961
WARNING:telethon.network.mtprotosender:Attempt 1 at connecting failed: OSError: [WinError 1232] The network location cannot be reached. For information about network troubleshooting, see Windows Help
WARNING:telethon.network.mtprotosender:Attempt 2 at connecting failed: OSError: [WinError 1232] The network location cannot be reached. For information about network troubleshooting, see Windows Help
WARNING:telethon.network.mtprotosender:Attempt 3 at connecting failed: OSError: [WinError 1232] The network location cannot be reached. For information about network troubleshooting, see Windows Help
WARNING:telethon.network.mtprotosender:Attempt 4 at connecting failed: OSError: [WinError 1232] The network location cannot be reached. For information about network troubleshooting, see Windows Help
WARNING:telethon.network.mtprotosender:Attempt 5 at connecting failed: OSError: [WinError 1232] The network location cannot be reached. For information about network troubleshooting, see Windows Help
WARNING:telethon.network.mtprotosender:Attempt 6 at connecting failed: OSError: [WinError 1232] The network location cannot be reached. For information about network troubleshooting, see Windows Help
WARNING:telethon.network.mtprotosender:Attempt 1 at connecting failed: OSError: [WinError 1232] The network location cannot be reached. For information about network troubleshooting, see Windows Help
WARNING:telethon.network.mtprotosender:Attempt 2 at connecting failed: OSError: [WinError 1232] The network location cannot be reached. For information about network troubleshooting, see Windows Help
WARNING:telethon.network.mtprotosender:Attempt 3 at connecting failed: OSError: [WinError 1232] The network location cannot be reached. For information about network troubleshooting, see Windows Help
WARNING:telethon.network.mtprotosender:Attempt 4 at connecting failed: OSError: [WinError 1232] The network location cannot be reached. For information about network troubleshooting, see Windows Help
WARNING:telethon.network.mtprotosender:Attempt 5 at connecting failed: OSError: [WinError 1232] The network location cannot be reached. For information about network troubleshooting, see Windows Help
WARNING:telethon.network.mtprotosender:Attempt 6 at connecting failed: OSError: [WinError 1232] The network location cannot be reached. For information about network troubleshooting, see Windows Help
WARNING:telethon.network.mtprotosender:Attempt 1 at connecting failed: OSError: [WinError 1232] The network location cannot be reached. For information about network troubleshooting, see Windows Help
WARNING:telethon.network.mtprotosender:Attempt 2 at connecting failed: OSError: [WinError 1232] The network location cannot be reached. For information about network troubleshooting, see Windows Help
WARNING:telethon.network.mtprotosender:Attempt 3 at connecting failed: OSError: [WinError 1232] The network location cannot be reached. For information about network troubleshooting, see Windows Help
WARNING:telethon.network.mtprotosender:Attempt 4 at connecting failed: OSError: [WinError 1232] The network location cannot be reached. For information about network troubleshooting, see Windows Help
WARNING:telethon.network.mtprotosender:Attempt 5 at connecting failed: OSError: [WinError 1232] The network location cannot be reached. For information about network troubleshooting, see Windows Help
WARNING:telethon.network.mtprotosender:Attempt 6 at connecting failed: OSError: [WinError 1232] The network location cannot be reached. For information about network troubleshooting, see Windows Help
WARNING:telethon.network.mtprotosender:Attempt 1 at connecting failed: OSError: [WinError 1232] The network location cannot be reached. For information about network troubleshooting, see Windows Help
WARNING:telethon.network.mtprotosender:Attempt 2 at connecting failed: OSError: [WinError 1232] The network location cannot be reached. For information about network troubleshooting, see Windows Help
WARNING:telethon.network.mtprotosender:Attempt 3 at connecting failed: OSError: [WinError 1232] The network location cannot be reached. For information about network troubleshooting, see Windows Help
WARNING:telethon.network.mtprotosender:Attempt 4 at connecting failed: OSError: [WinError 1232] The network location cannot be reached. For information about network troubleshooting, see Windows Help
WARNING:telethon.network.mtprotosender:Attempt 5 at connecting failed: OSError: [WinError 1232] The network location cannot be reached. For information about network troubleshooting, see Windows Help
WARNING:telethon.network.mtprotosender:Attempt 6 at connecting failed: OSError: [WinError 1232] The network location cannot be reached. For information about network troubleshooting, see Windows Help
WARNING:telethon.network.mtprotosender:Attempt 1 at connecting failed: OSError: [WinError 1232] The network location cannot be reached. For information about network troubleshooting, see Windows Help
WARNING:telethon.network.mtprotosender:Attempt 2 at connecting failed: OSError: [WinError 1232] The network location cannot be reached. For information about network troubleshooting, see Windows Help
WARNING:telethon.network.mtprotosender:Attempt 3 at connecting failed: OSError: [WinError 1232] The network location cannot be reached. For information about network troubleshooting, see Windows Help
WARNING:telethon.network.mtprotosender:Attempt 4 at connecting failed: OSError: [WinError 1232] The network location cannot be reached. For information about network troubleshooting, see Windows Help
WARNING:telethon.network.mtprotosender:Attempt 5 at connecting failed: OSError: [WinError 1232] The network location cannot be reached. For information about network troubleshooting, see Windows Help
WARNING:telethon.network.mtprotosender:Attempt 6 at connecting failed: OSError: [WinError 1232] The network location cannot be reached. For information about network troubleshooting, see Windows Help
ERROR:telethon.network.mtprotosender:Automatic reconnection failed 5 time(s)
ERROR:asyncio:Future exception was never retrieved
future: <Future finished exception=ConnectionError('Connection to Telegram failed 5 time(s)')>
ConnectionError: Connection to Telegram failed 5 time(s)
